Workbook
Name Area_Unit: [1]Intro!$I$8
Name BigNumber: 100000000
Name CALC: #REF!
Name Capex_sensitivity: [2]Dashboard!$N$17
Name CHECK: #REF!
Name CPI: #REF!
Name CPI_St: #REF!
Name Currency: [1]Intro!$I$6
Name days_in_month: 30
Name Days_in_Yr: #REF!
Name Days_per_Year: 365
Name Debtproportion_sensitivity: [2]Dashboard!$C$20
Name DynamicChart: '[2]Graph data'!A7:OFFSET('[2]Graph data'!A7,11,'[2]Graph data'!$Q$13)
Name Enddate: 54788
Name hours_per_day: 24
Name INPUT: #REF!
Name Landcost_sensitivity: [2]Dashboard!$N$18
Name Leaseexp_sensitivity: [2]Dashboard!$N$20
Name Million: #REF!
Name Monthly: [2]Global!$J$69
Name Months_per_Year: 12
Name Occupancy_sensitivity: [2]Dashboard!$N$16
Name Optcost_sensitivity: [2]Dashboard!$N$19
Name P1_PS_End_Date: #REF!
Name P1_PS_ST_Date: #REF!
Name P1_SDC_End_Date: #REF!
Name P1_SDC_St_Date: #REF!
Name P2_End_date: #REF!
Name P2_St_Date: #REF!
Name ProjStartDate: [1]Intro!$I$10
Name quarter: 0.25
Name Quarterly: [2]Global!$J$68
Name Revenue_sensitivity: [2]Dashboard!$N$15
Name rngCrncy: [3]Settings!$E$61
Name rngModelName: [4]Global!$E$16
Name rngProjName: [4]Global!$E$15
Name SemiAnnually: [2]Global!$J$67
Name Thousand: 1000
Name Todaydate: 42004
Name Unit_cent: 100
Name Unit_k: 1000
Name Unit_mn: 1000000
Name Units: 1000
Name Weekly: [2]Global!$J$70
Name z_ActivePeriods: '[2]Graph data'!$R$6:OFFSET('[2]Graph data'!$R$6,,'[2]Graph data'!$Q$13)
Name z_Constructionphase: ('[2]General Input'!$R$6:OFFSET('[2]General Input'!$R$6,,'[2]General Input'!$J$17/12-1))
Name z_EBITDAMargin: '[2]Graph data'!$R$33:OFFSET('[2]Graph data'!$R$33,,'[2]Graph data'!$Q$13)
Name z_EBIZMargin: '[2]Graph data'!$R$34:OFFSET('[2]Graph data'!$R$34,,'[2]Graph data'!$Q$13)
Name z_Entertainment_LeisureRevenue: '[2]Graph data'!$R$23:OFFSET('[2]Graph data'!$R$23,,'[2]Graph data'!$Q$13)
Name z_EntertainmentType: [2]Headings!#REF!
Name z_FinancingCash: '[2]Graph data'!$R$41:OFFSET('[2]Graph data'!$R$41,,'[2]Graph data'!$Q$13)
Name z_HospitalityRevenue: '[2]Graph data'!$R$18:OFFSET('[2]Graph data'!$R$18,,'[2]Graph data'!$Q$13)
Name z_IndustrialRevenue: '[2]Graph data'!$R$19:OFFSET('[2]Graph data'!$R$19,,'[2]Graph data'!$Q$13)
Name z_InvestingCash: '[2]Graph data'!$R$40:OFFSET('[2]Graph data'!$R$40,,'[2]Graph data'!$Q$13)
Name z_LaborAccomodationRevenue: '[2]Graph data'!$R$22:OFFSET('[2]Graph data'!$R$22,,'[2]Graph data'!$Q$13)
Name z_LandRevenue: '[2]Graph data'!$R$21:OFFSET('[2]Graph data'!$R$21,,'[2]Graph data'!$Q$13)
Name z_OfficeRevenue: '[2]Graph data'!$R$17:OFFSET('[2]Graph data'!$R$17,,'[2]Graph data'!$Q$13)
Name z_OperatingCash: '[2]Graph data'!$R$39:OFFSET('[2]Graph data'!$R$39,,'[2]Graph data'!$Q$13)
Name z_PATMargin: '[2]Graph data'!$R$36:OFFSET('[2]Graph data'!$R$36,,'[2]Graph data'!$Q$13)
Name z_PBTMargin: '[2]Graph data'!$R$35:OFFSET('[2]Graph data'!$R$35,,'[2]Graph data'!$Q$13)

Sheet Cover
B2: MAAD RESIDENTIAL
B3: Financial Feasibility Model
B5: PROJECT OVERVIEW
B6: Project name | C6: MAAD Residential - Mixed-use (Phase 1, 2 & 3)
B7: Asset mix | C7: Branded apartments (T2-T5), Tower 01, Hotel 01, Support Retail
B8: Currency | C8: SAR '000
B9: Time horizon | C9: 15 years (2025-2039), annual
B10: P&L scope | C10: Operating P&L to EBITDA only
B11: Source model | C11: MAAD Feasibility Scenario 7.0.xlsb
B13: WORKBOOK CONTENTS
B14: Tab | C14: Description
B15: Cover | C15: Project overview, contents, key headlines
B16: Revenue | C16: Pre-sales schedule + revenue build (residential, hospitality, retail)
B17: Costs | C17: Hospitality + retail OpEx with NOP / NOI methodology and AP working-capital adjustment
B18: Capex | C18: Asset cost stack (5 assets, sub-units, land), depreciation schedule
B19: Debt | C19: T1 (SNB Phase 1) + T2 (Phase 2 & 3) debt facilities, IDC, equity contribution
B20: CF | C20: Cash flow statement: revenue → costs → capex → financing → closing cash
B21: P&L | C21: Income Statement: Revenue → CoS → OpEx → NOI → D&A → EBIZ → PBZ → PAZ
B22: Wafi Escrow | C22: Per-asset cost-of-sales margin curve, REGA / Wafi escrow split, CF impact
B23: Land Summary | C23: Land area, price and value by sub-asset and phase; sourced by Capex tab
B24: Review Summary | C24: Snapshot of key totals plus consolidated variance vs KPMG (Source MAAD, Phase 2&3-only)
B26: KEY HEADLINES
B27: Metric | C27: SAR'000 | D27: Source
B28: Total Revenue Received (horizon) | C28: =CF!E21 -> 14527965 | D28: CF!D19
B29: Total Costs Paid (incl. Zakat) | C29: =CF!E37 -> -4506729.5 | D29: CF!D27
B30: Exit Value (2039) | C30: =CF!E39 -> 4996382.7 | D30: CF!D29
B31: Cash Flow from Operations (horizon) | C31: =CF!E40 -> 15819785 | D31: CF!D30
B32: Net Operating Income (P&L) | C32: ='P&L'!D45 -> 5703056.7 | D32: P&L!D44
B33: EBIZ (Earnings before interest & zakat) | C33: ='P&L'!D49 -> 5475571.8 | D33: P&L!D55
B34: Profit before Zakat (PBZ) | C34: ='P&L'!D55 -> 4388524.2 | D34: P&L!D61
B35: Profit after Zakat (PAZ) | C35: ='P&L'!D59 -> 4278811.1 | D35: P&L!D65
B36: Total Capex (Excl. Land) | C36: =Capex!K197 -> 3561464.5 | D36: Capex!K186
B37: Total Land Cost | C37: =Capex!K210 -> 1350681.9 | D37: Capex!K199
B38: Total Capex (Incl. Land) | C38: =Capex!K223 -> 4912146.4 | D38: Capex!K212
B39: Total Land Value | C39: =Debt!F9 -> 2408189 | D39: Debt!F8
B40: Land Value Phase 2 & 3 | C40: =Debt!F10 -> 1350681.9 | D40: Debt!F9
B41: Land Value Phase 1 | C41: =Debt!F11 -> 1057507.1 | D41: Debt!F10
B42: Pre-Capex VOCO | C42: =Debt!F12 -> 2624544 | D42: Debt!F11
B43: Total Pre-Capex (Land P1 + VOCO) | C43: =Debt!F13 -> 3682051 | D43: Debt!F12
B44: Tranche 1 Facility (SNB) | C44: =Debt!F15 -> 2400000 | D44: Debt!F14
...

Sheet Revenue
B1: MAAD RESIDENTIAL WITH HOTEL - REVENUE
B2: All figures in SAR'000
B3: Pre-sales schedule + revenue build for residential, hospitality and retail (15-yr horizon).
C4: DESCRIPTION | D4: Phase | E4: uom | J4: Total | L4: 2025 | M4: =L4+1 -> 2026 | N4: =M4+1 -> 2027 | O4: =N4+1 -> 2028 | P4: =O4+1 -> 2029 | Q4: =P4+1 -> 2030 | R4: =Q4+1 -> 2031 | S4: =R4+1 -> 2032 | T4: =S4+1 -> 2033 | ... Z4: =Y4+1 -> 2039
C6: Period | E6: SAR'000 | G6: 1000 | L6: =K6+1 -> 1 | M6: =L6+1 -> 2 | N6: =M6+1 -> 3 | O6: =N6+1 -> 4 | P6: =O6+1 -> 5 | Q6: =P6+1 -> 6 | R6: =Q6+1 -> 7 | S6: =R6+1 -> 8 | ... Z6: =Y6+1 -> 15
B7: Revenue Summary
C8: Residential Revenue | J8: =SUM(L8:Z8) -> 6408977 | L8: =L22 -> 0 | M8: =M22 -> 37769.536 | N8: =N22 -> 725615.39 | O8: =O22 -> 1719744.3 | P8: =P22 -> 2002224.2 | Q8: =Q22 -> 1578069.8 | R8: =R22 -> 345553.85 | S8: =S22 -> 0 | ... Z8: =Z22 -> 0
C9: Hospitality Revenue | J9: =SUM(L9:Z9) -> 7782977.7 | L9: =L226 -> 0 | M9: =M226 -> 323867.37 | N9: =N226 -> 336217.37 | O9: =O226 -> 348567.37 | P9: =P226 -> 472864.73 | Q9: =Q226 -> 505432.65 | R9: =R226 -> 555815.71 | S9: =S226 -> 589664.3 | ... Z9: =Z226 -> 724616.46
C10: Retail Revenue | J10: =SUM(L10:Z10) -> 336010.5 | L10: =L326 -> 0 | M10: =M326 -> 0 | N10: =N326 -> 0 | O10: =O326 -> 0 | P10: =P326 -> 14651.584 | Q10: =Q326 -> 20023.831 | R10: =R326 -> 25655.534 | S10: =S326 -> 31556.306 | ... Z10: =Z326 -> 37510.532
B11: Total Pre-Sales Revenue Received - CF | J11: =SUM(J7:J10) -> 14527965 | L11: =SUM(L7:L10) -> 0 | M11: =SUM(M7:M10) -> 361636.91 | N11: =SUM(N7:N10) -> 1061832.8 | O11: =SUM(O7:O10) -> 2068311.7 | P11: =SUM(P7:P10) -> 2489740.5 | Q11: =SUM(Q7:Q10) -> 2103526.3 | R11: =SUM(R7:R10) -> 927025.09 | S11: =SUM(S7:S10) -> 621220.61 | ... Z11: =SUM(Z7:Z10) -> 762126.99
B13: Residential Revenue
B15: Pre-Sales Revenue Received
C16: Pre-Sales from Branded Apartments T2 & T3 | D16: 2 | J16: =SUM(L16:Z16) -> 2539826.9 | L16: =L51 -> 0 | M16: =M51 -> 28221.416 | N16: =N51 -> 465636.61 | O16: =O51 -> 973601.98 | P16: =P51 -> 945375.54 | Q16: =Q51 -> 126991.34 | R16: =R51 -> 0 | S16: =S51 -> 0 | ... Z16: =Z51 -> 0
C17: Pre-Sales from Branded Apartments T4 & T5 | D17: 3 | J17: =SUM(L17:Z17) -> 1594797 | L17: =L80 -> 0 | M17: =M80 -> 0 | N17: =N80 -> 106319.8 | O17: =O80 -> 425279.2 | P17: =P80 -> 744238.6 | Q17: =Q80 -> 239219.55 | R17: =R80 -> 79739.85 | S17: =S80 -> 0 | ... Z17: =Z80 -> 0
C18: Pre-Sales from Residential Tower 01 | D18: 2 | J18: =SUM(L18:Z18) -> 838610.8 | L18: =L112 -> 0 | M18: =M112 -> 9548.12 | N18: =N112 -> 153658.98 | O18: =O112 -> 320863.14 | P18: =P112 -> 312610.02 | Q18: =Q112 -> 41930.54 | R18: =R112 -> 0 | S18: =S112 -> 0 | ... Z18: =Z112 -> 0
C19: Branded Apartments T2 & T3 | D19: 2 | J19: =SUM(L19:Z19) -> 282214.16 | L19: =L129 -> 0 | M19: =M129 -> 0 | N19: =N129 -> 0 | O19: =O129 -> 0 | P19: =P129 -> 0 | Q19: =Q129 -> 282214.16 | R19: =R129 -> 0 | S19: =S129 -> 0 | ... Z19: =Z129 -> 0
C20: Branded Apartments T4 & T5 | D20: 3 | J20: =SUM(L20:Z20) -> 1063227 | L20: =L144 -> 0 | M20: =M144 -> 0 | N20: =N144 -> 0 | O20: =O144 -> 0 | P20: =P144 -> 0 | Q20: =Q144 -> 797413 | R20: =R144 -> 265814 | S20: =S144 -> 0 | ... Z20: =Z144 -> 0
C21: Residential Tower 01 | D21: 3 | J21: =SUM(L21:Z21) -> 90301.2 | L21: =L162 -> 0 | M21: =M162 -> 0 | N21: =N162 -> 0 | O21: =O162 -> 0 | P21: =P162 -> 0 | Q21: =Q162 -> 90301.2 | R21: =R162 -> 0 | S21: =S162 -> 0 | ... Z21: =Z162 -> 0
C22: Total Pre-Sales Revenue Received | J22: =SUM(J16:J21) -> 6408977 | L22: =SUM(L16:L21) -> 0 | M22: =SUM(M16:M21) -> 37769.536 | N22: =SUM(N16:N21) -> 725615.39 | O22: =SUM(O16:O21) -> 1719744.3 | P22: =SUM(P16:P21) -> 2002224.2 | Q22: =SUM(Q16:Q21) -> 1578069.8 | R22: =SUM(R16:R21) -> 345553.85 | S22: =SUM(S16:S21) -> 0 | ... Z22: =SUM(Z16:Z21) -> 0
B24: Pre-Sales from Branded Apartments T2 & T3 | D24: 2
C25: Indexation Factor | E25: % | G25: 0 | L25: =(1+$G25)^L$6 -> 1 | M25: =(1+$G25)^M$6 -> 1 | N25: =(1+$G25)^N$6 -> 1 | O25: =(1+$G25)^O$6 -> 1 | P25: =(1+$G25)^P$6 -> 1 | Q25: =(1+$G25)^Q$6 -> 1 | R25: =(1+$G25)^R$6 -> 1 | S25: =(1+$G25)^S$6 -> 1 | ... Z25: =(1+$G25)^Z$6 -> 1
C27: Pre-Sales from Branded Apartments T2 & T3 | G27: Area SQM | H27: SAR/SQM
C28: 1 BR | G28: 47800 | H28: 33456.067 | L28: 0 | M28: 0.05 | N28: 0.3 | O28: 0.3 | P28: 0.25 | Q28: 0 | R28: 0 | S28: 0 | T28: 0 | U28: 0 | V28: 0 | W28: 0 | X28: 0 | Y28: 0 | Z28: 0
C29: 2 BR | G29: 36497.1 | H29: 33505.248 | L29: 0 | M29: 0.05 | N29: 0.3 | O29: 0.3 | P29: 0.25 | Q29: 0 | R29: 0 | S29: 0 | T29: 0 | U29: 0 | V29: 0 | W29: 0 | X29: 0 | Y29: 0 | Z29: 0
C31: Pre-Sale Area
C32: 1 BR | E32: Area SQM | G32: {=SUM($L28:$Z28*$G28)} -> 43020 | J32: =SUM(L32:Z32) -> 43020 | L32: =ROUND($G28*L28,0) -> 0 | M32: =ROUND($G28*M28,0) -> 2390 | N32: =ROUND($G28*N28,0) -> 14340 | O32: =ROUND($G28*O28,0) -> 14340 | P32: =ROUND($G28*P28,0) -> 11950 | Q32: =ROUND($G28*Q28,0) -> 0 | R32: =ROUND($G28*R28,0) -> 0 | S32: =ROUND($G28*S28,0) -> 0 | ... Z32: =ROUND($G28*Z28,0) -> 0
C33: 2 BR | E33: Area SQM | G33: {=SUM($L29:$Z29*$G29)} -> 32847.39 | J33: =SUM(L33:Z33) -> 32847 | L33: =ROUND($G29*L29,0) -> 0 | M33: =ROUND($G29*M29,0) -> 1825 | N33: =ROUND($G29*N29,0) -> 10949 | O33: =ROUND($G29*O29,0) -> 10949 | P33: =ROUND($G29*P29,0) -> 9124 | Q33: =ROUND($G29*Q29,0) -> 0 | R33: =ROUND($G29*R29,0) -> 0 | S33: =ROUND($G29*S29,0) -> 0 | ... Z33: =ROUND($G29*Z29,0) -> 0
C34: Total Area | E34: Area SQM | G34: =SUM(G32:G33) -> 75867.39 | J34: =SUM(J32:J33) -> 75867 | L34: =SUM(L32:L33) -> 0 | M34: =SUM(M32:M33) -> 4215 | N34: =SUM(N32:N33) -> 25289 | O34: =SUM(O32:O33) -> 25289 | P34: =SUM(P32:P33) -> 21074 | Q34: =SUM(Q32:Q33) -> 0 | R34: =SUM(R32:R33) -> 0 | S34: =SUM(S32:S33) -> 0 | ... Z34: =SUM(Z32:Z33) -> 0
C36: Pre sales
C37: 1 BR | E37: SAR'000 | G37: =$H28 -> 33456.067 | J37: =SUM(L37:Z37) -> 1439280 | L37: =(($G37*L$25)*L32)/$G$6 -> 0 | M37: =(($G37*M$25)*M32)/$G$6 -> 79960 | N37: =(($G37*N$25)*N32)/$G$6 -> 479760 | O37: =(($G37*O$25)*O32)/$G$6 -> 479760 | P37: =(($G37*P$25)*P32)/$G$6 -> 399800 | Q37: =(($G37*Q$25)*Q32)/$G$6 -> 0 | R37: =(($G37*R$25)*R32)/$G$6 -> 0 | S37: =(($G37*S$25)*S32)/$G$6 -> 0 | ... Z37: =(($G37*Z$25)*Z32)/$G$6 -> 0
C38: 2 BR | E38: SAR'000 | G38: =$H29 -> 33505.248 | J38: =SUM(L38:Z38) -> 1100546.9 | L38: =(($G38*L$25)*L33)/$G$6 -> 0 | M38: =(($G38*M$25)*M33)/$G$6 -> 61147.078 | N38: =(($G38*N$25)*N33)/$G$6 -> 366848.96 | O38: =(($G38*O$25)*O33)/$G$6 -> 366848.96 | P38: =(($G38*P$25)*P33)/$G$6 -> 305701.89 | Q38: =(($G38*Q$25)*Q33)/$G$6 -> 0 | R38: =(($G38*R$25)*R33)/$G$6 -> 0 | S38: =(($G38*S$25)*S33)/$G$6 -> 0 | ... Z38: =(($G38*Z$25)*Z33)/$G$6 -> 0
C39: Total Pre Sales | E39: SAR'000 | G39: =AVERAGE(G37:G38) -> 33480.658 | J39: =SUM(L39:Z39) -> 2539826.9 | L39: =SUM(L37:L38) -> 0 | M39: =SUM(M37:M38) -> 141107.08 | N39: =SUM(N37:N38) -> 846608.96 | O39: =SUM(O37:O38) -> 846608.96 | P39: =SUM(P37:P38) -> 705501.89 | Q39: =SUM(Q37:Q38) -> 0 | R39: =SUM(R37:R38) -> 0 | S39: =SUM(S37:S38) -> 0 | ... Z39: =SUM(Z37:Z38) -> 0
C41: Cumulative cash payment profile
C42: Cash Payment Profile | E42: % | L42: 0 | M42: 0.2 | N42: 0.3 | O42: 0.3 | P42: 0.15 | Q42: 0.05 | R42: 0 | S42: 0 | T42: 0 | U42: 0 | V42: 0 | W42: 0 | X42: 0 | Y42: 0 | Z42: 0
C43: Cumulative Payment Profile | E43: % | L43: =K43+L42 -> 0 | M43: =L43+M42 -> 0.2 | N43: =M43+N42 -> 0.5 | O43: =N43+O42 -> 0.8 | P43: =O43+P42 -> 0.95 | Q43: =P43+Q42 -> 1 | R43: =Q43+R42 -> 1 | S43: =R43+S42 -> 1 | ... Z43: =Y43+Z42 -> 1
C45: 2025 | E45: SAR'000 | G45: =SUMIF($L$4:$Z$4,$C45,$L$39:$Z$39) -> 0 | J45: =SUM(L45:Z45) -> 0 | L45: {=IF(L$4<$C45,0,IF(L$4=$C45,SUMIF($L$4:$Z$4,$C45,$L$39:$Z$39)*INDEX($L$43:$Z$43,$C45-$L$4+1),SUMIF($L$4:$Z$4,$C45,$L$39:$Z$39)*L$42))} -> 0 | M45: {=IF(M$4<$C45,0,IF(M$4=$C45,SUMIF($L$4:$Z$4,$C45,$L$39:$Z$39)*INDEX($L$43:$Z$43,$C45-$L$4+1),SUMIF($L$4:$Z$4,$C45,$L$39:$Z$39)*M$42))} -> 0 | N45: {=IF(N$4<$C45,0,IF(N$4=$C45,SUMIF($L$4:$Z$4,$C45,$L$39:$Z$39)*INDEX($L$43:$Z$43,$C45-$L$4+1),SUMIF($L$4:$Z$4,$C45,$L$39:$Z$39)*N$42))} -> 0 | O45: {=IF(O$4<$C45,0,IF(O$4=$C45,SUMIF($L$4:$Z$4,$C45,$L$39:$Z$39)*INDEX($L$43:$Z$43,$C45-$L$4+1),SUMIF($L$4:$Z$4,$C45,$L$39:$Z$39)*O$42))} -> 0 | P45: {=IF(P$4<$C45,0,IF(P$4=$C45,SUMIF($L$4:$Z$4,$C45,$L$39:$Z$39)*INDEX($L$43:$Z$43,$C45-$L$4+1),SUMIF($L$4:$Z$4,$C45,$L$39:$Z$39)*P$42))} -> 0 | Q45: {=IF(Q$4<$C45,0,IF(Q$4=$C45,SUMIF($L$4:$Z$4,$C45,$L$39:$Z$39)*INDEX($L$43:$Z$43,$C45-$L$4+1),SUMIF($L$4:$Z$4,$C45,$L$39:$Z$39)*Q$42))} -> 0 | R45: {=IF(R$4<$C45,0,IF(R$4=$C45,SUMIF($L$4:$Z$4,$C45,$L$39:$Z$39)*INDEX($L$43:$Z$43,$C45-$L$4+1),SUMIF($L$4:$Z$4,$C45,$L$39:$Z$39)*R$42))} -> 0 | S45: {=IF(S$4<$C45,0,IF(S$4=$C45,SUMIF($L$4:$Z$4,$C45,$L$39:$Z$39)*INDEX($L$43:$Z$43,$C45-$L$4+1),SUMIF($L$4:$Z$4,$C45,$L$39:$Z$39)*S$42))} -> 0 | ... Z45: {=IF(Z$4<$C45,0,IF(Z$4=$C45,SUMIF($L$4:$Z$4,$C45,$L$39:$Z$39)*INDEX($L$43:$Z$43,$C45-$L$4+1),SUMIF($L$4:$Z$4,$C45,$L$39:$Z$39)*Z$42))} -> 0
C46: =C45+1 -> 2026 | E46: SAR'000 | G46: =SUMIF($L$4:$Z$4,$C46,$L$39:$Z$39) -> 141107.08 | J46: =SUM(L46:Z46) -> 141107.08 | L46: {=IF(L$4<$C46,0,IF(L$4=$C46,SUMIF($L$4:$Z$4,$C46,$L$39:$Z$39)*INDEX($L$43:$Z$43,$C46-$L$4+1),SUMIF($L$4:$Z$4,$C46,$L$39:$Z$39)*L$42))} -> 0 | M46: {=IF(M$4<$C46,0,IF(M$4=$C46,SUMIF($L$4:$Z$4,$C46,$L$39:$Z$39)*INDEX($L$43:$Z$43,$C46-$L$4+1),SUMIF($L$4:$Z$4,$C46,$L$39:$Z$39)*M$42))} -> 28221.416 | N46: {=IF(N$4<$C46,0,IF(N$4=$C46,SUMIF($L$4:$Z$4,$C46,$L$39:$Z$39)*INDEX($L$43:$Z$43,$C46-$L$4+1),SUMIF($L$4:$Z$4,$C46,$L$39:$Z$39)*N$42))} -> 42332.123 | O46: {=IF(O$4<$C46,0,IF(O$4=$C46,SUMIF($L$4:$Z$4,$C46,$L$39:$Z$39)*INDEX($L$43:$Z$43,$C46-$L$4+1),SUMIF($L$4:$Z$4,$C46,$L$39:$Z$39)*O$42))} -> 42332.123 | P46: {=IF(P$4<$C46,0,IF(P$4=$C46,SUMIF($L$4:$Z$4,$C46,$L$39:$Z$39)*INDEX($L$43:$Z$43,$C46-$L$4+1),SUMIF($L$4:$Z$4,$C46,$L$39:$Z$39)*P$42))} -> 21166.062 | Q46: {=IF(Q$4<$C46,0,IF(Q$4=$C46,SUMIF($L$4:$Z$4,$C46,$L$39:$Z$39)*INDEX($L$43:$Z$43,$C46-$L$4+1),SUMIF($L$4:$Z$4,$C46,$L$39:$Z$39)*Q$42))} -> 7055.3539 | R46: {=IF(R$4<$C46,0,IF(R$4=$C46,SUMIF($L$4:$Z$4,$C46,$L$39:$Z$39)*INDEX($L$43:$Z$43,$C46-$L$4+1),SUMIF($L$4:$Z$4,$C46,$L$39:$Z$39)*R$42))} -> 0 | S46: {=IF(S$4<$C46,0,IF(S$4=$C46,SUMIF($L$4:$Z$4,$C46,$L$39:$Z$39)*INDEX($L$43:$Z$43,$C46-$L$4+1),SUMIF($L$4:$Z$4,$C46,$L$39:$Z$39)*S$42))} -> 0 | ... Z46: {=IF(Z$4<$C46,0,IF(Z$4=$C46,SUMIF($L$4:$Z$4,$C46,$L$39:$Z$39)*INDEX($L$43:$Z$43,$C46-$L$4+1),SUMIF($L$4:$Z$4,$C46,$L$39:$Z$39)*Z$42))} -> 0
C47: =C46+1 -> 2027 | E47: SAR'000 | G47: =SUMIF($L$4:$Z$4,$C47,$L$39:$Z$39) -> 846608.96 | J47: =SUM(L47:Z47) -> 846608.96 | L47: {=IF(L$4<$C47,0,IF(L$4=$C47,SUMIF($L$4:$Z$4,$C47,$L$39:$Z$39)*INDEX($L$43:$Z$43,$C47-$L$4+1),SUMIF($L$4:$Z$4,$C47,$L$39:$Z$39)*L$42))} -> 0 | M47: {=IF(M$4<$C47,0,IF(M$4=$C47,SUMIF($L$4:$Z$4,$C47,$L$39:$Z$39)*INDEX($L$43:$Z$43,$C47-$L$4+1),SUMIF($L$4:$Z$4,$C47,$L$39:$Z$39)*M$42))} -> 0 | N47: {=IF(N$4<$C47,0,IF(N$4=$C47,SUMIF($L$4:$Z$4,$C47,$L$39:$Z$39)*INDEX($L$43:$Z$43,$C47-$L$4+1),SUMIF($L$4:$Z$4,$C47,$L$39:$Z$39)*N$42))} -> 423304.48 | O47: {=IF(O$4<$C47,0,IF(O$4=$C47,SUMIF($L$4:$Z$4,$C47,$L$39:$Z$39)*INDEX($L$43:$Z$43,$C47-$L$4+1),SUMIF($L$4:$Z$4,$C47,$L$39:$Z$39)*O$42))} -> 253982.69 | P47: {=IF(P$4<$C47,0,IF(P$4=$C47,SUMIF($L$4:$Z$4,$C47,$L$39:$Z$39)*INDEX($L$43:$Z$43,$C47-$L$4+1),SUMIF($L$4:$Z$4,$C47,$L$39:$Z$39)*P$42))} -> 126991.34 | Q47: {=IF(Q$4<$C47,0,IF(Q$4=$C47,SUMIF($L$4:$Z$4,$C47,$L$39:$Z$39)*INDEX($L$43:$Z$43,$C47-$L$4+1),SUMIF($L$4:$Z$4,$C47,$L$39:$Z$39)*Q$42))} -> 42330.448 | R47: {=IF(R$4<$C47,0,IF(R$4=$C47,SUMIF($L$4:$Z$4,$C47,$L$39:$Z$39)*INDEX($L$43:$Z$43,$C47-$L$4+1),SUMIF($L$4:$Z$4,$C47,$L$39:$Z$39)*R$42))} -> 0 | S47: {=IF(S$4<$C47,0,IF(S$4=$C47,SUMIF($L$4:$Z$4,$C47,$L$39:$Z$39)*INDEX($L$43:$Z$43,$C47-$L$4+1),SUMIF($L$4:$Z$4,$C47,$L$39:$Z$39)*S$42))} -> 0 | ... Z47: {=IF(Z$4<$C47,0,IF(Z$4=$C47,SUMIF($L$4:$Z$4,$C47,$L$39:$Z$39)*INDEX($L$43:$Z$43,$C47-$L$4+1),SUMIF($L$4:$Z$4,$C47,$L$39:$Z$39)*Z$42))} -> 0
C48: =C47+1 -> 2028 | E48: SAR'000 | G48: =SUMIF($L$4:$Z$4,$C48,$L$39:$Z$39) -> 846608.96 | J48: =SUM(L48:Z48) -> 846608.96 | L48: {=IF(L$4<$C48,0,IF(L$4=$C48,SUMIF($L$4:$Z$4,$C48,$L$39:$Z$39)*INDEX($L$43:$Z$43,$C48-$L$4+1),SUMIF($L$4:$Z$4,$C48,$L$39:$Z$39)*L$42))} -> 0 | M48: {=IF(M$4<$C48,0,IF(M$4=$C48,SUMIF($L$4:$Z$4,$C48,$L$39:$Z$39)*INDEX($L$43:$Z$43,$C48-$L$4+1),SUMIF($L$4:$Z$4,$C48,$L$39:$Z$39)*M$42))} -> 0 | N48: {=IF(N$4<$C48,0,IF(N$4=$C48,SUMIF($L$4:$Z$4,$C48,$L$39:$Z$39)*INDEX($L$43:$Z$43,$C48-$L$4+1),SUMIF($L$4:$Z$4,$C48,$L$39:$Z$39)*N$42))} -> 0 | O48: {=IF(O$4<$C48,0,IF(O$4=$C48,SUMIF($L$4:$Z$4,$C48,$L$39:$Z$39)*INDEX($L$43:$Z$43,$C48-$L$4+1),SUMIF($L$4:$Z$4,$C48,$L$39:$Z$39)*O$42))} -> 677287.17 | P48: {=IF(P$4<$C48,0,IF(P$4=$C48,SUMIF($L$4:$Z$4,$C48,$L$39:$Z$39)*INDEX($L$43:$Z$43,$C48-$L$4+1),SUMIF($L$4:$Z$4,$C48,$L$39:$Z$39)*P$42))} -> 126991.34 | Q48: {=IF(Q$4<$C48,0,IF(Q$4=$C48,SUMIF($L$4:$Z$4,$C48,$L$39:$Z$39)*INDEX($L$43:$Z$43,$C48-$L$4+1),SUMIF($L$4:$Z$4,$C48,$L$39:$Z$39)*Q$42))} -> 42330.448 | R48: {=IF(R$4<$C48,0,IF(R$4=$C48,SUMIF($L$4:$Z$4,$C48,$L$39:$Z$39)*INDEX($L$43:$Z$43,$C48-$L$4+1),SUMIF($L$4:$Z$4,$C48,$L$39:$Z$39)*R$42))} -> 0 | S48: {=IF(S$4<$C48,0,IF(S$4=$C48,SUMIF($L$4:$Z$4,$C48,$L$39:$Z$39)*INDEX($L$43:$Z$43,$C48-$L$4+1),SUMIF($L$4:$Z$4,$C48,$L$39:$Z$39)*S$42))} -> 0 | ... Z48: {=IF(Z$4<$C48,0,IF(Z$4=$C48,SUMIF($L$4:$Z$4,$C48,$L$39:$Z$39)*INDEX($L$43:$Z$43,$C48-$L$4+1),SUMIF($L$4:$Z$4,$C48,$L$39:$Z$39)*Z$42))} -> 0
C49: =C48+1 -> 2029 | E49: SAR'000 | G49: =SUMIF($L$4:$Z$4,$C49,$L$39:$Z$39) -> 705501.89 | J49: =SUM(L49:Z49) -> 705501.89 | L49: {=IF(L$4<$C49,0,IF(L$4=$C49,SUMIF($L$4:$Z$4,$C49,$L$39:$Z$39)*INDEX($L$43:$Z$43,$C49-$L$4+1),SUMIF($L$4:$Z$4,$C49,$L$39:$Z$39)*L$42))} -> 0 | M49: {=IF(M$4<$C49,0,IF(M$4=$C49,SUMIF($L$4:$Z$4,$C49,$L$39:$Z$39)*INDEX($L$43:$Z$43,$C49-$L$4+1),SUMIF($L$4:$Z$4,$C49,$L$39:$Z$39)*M$42))} -> 0 | N49: {=IF(N$4<$C49,0,IF(N$4=$C49,SUMIF($L$4:$Z$4,$C49,$L$39:$Z$39)*INDEX($L$43:$Z$43,$C49-$L$4+1),SUMIF($L$4:$Z$4,$C49,$L$39:$Z$39)*N$42))} -> 0 | O49: {=IF(O$4<$C49,0,IF(O$4=$C49,SUMIF($L$4:$Z$4,$C49,$L$39:$Z$39)*INDEX($L$43:$Z$43,$C49-$L$4+1),SUMIF($L$4:$Z$4,$C49,$L$39:$Z$39)*O$42))} -> 0 | P49: {=IF(P$4<$C49,0,IF(P$4=$C49,SUMIF($L$4:$Z$4,$C49,$L$39:$Z$39)*INDEX($L$43:$Z$43,$C49-$L$4+1),SUMIF($L$4:$Z$4,$C49,$L$39:$Z$39)*P$42))} -> 670226.79 | Q49: {=IF(Q$4<$C49,0,IF(Q$4=$C49,SUMIF($L$4:$Z$4,$C49,$L$39:$Z$39)*INDEX($L$43:$Z$43,$C49-$L$4+1),SUMIF($L$4:$Z$4,$C49,$L$39:$Z$39)*Q$42))} -> 35275.094 | R49: {=IF(R$4<$C49,0,IF(R$4=$C49,SUMIF($L$4:$Z$4,$C49,$L$39:$Z$39)*INDEX($L$43:$Z$43,$C49-$L$4+1),SUMIF($L$4:$Z$4,$C49,$L$39:$Z$39)*R$42))} -> 0 | S49: {=IF(S$4<$C49,0,IF(S$4=$C49,SUMIF($L$4:$Z$4,$C49,$L$39:$Z$39)*INDEX($L$43:$Z$43,$C49-$L$4+1),SUMIF($L$4:$Z$4,$C49,$L$39:$Z$39)*S$42))} -> 0 | ... Z49: {=IF(Z$4<$C49,0,IF(Z$4=$C49,SUMIF($L$4:$Z$4,$C49,$L$39:$Z$39)*INDEX($L$43:$Z$43,$C49-$L$4+1),SUMIF($L$4:$Z$4,$C49,$L$39:$Z$39)*Z$42))} -> 0
...

Sheet Costs
B1: MAAD RESIDENTIAL WITH HOTEL - OPERATING COSTS
B2: All figures in SAR'000
B3: Hospitality + retail OpEx build with NOP / NOI methodology and accounts-payable working capital adjustment.
B4: DESCRIPTION | D4: Phase | F4: uom / basis | G4: Rate | H4: Total | J4: =Revenue!L4 -> 2025 | K4: =J4+1 -> 2026 | L4: =K4+1 -> 2027 | M4: =L4+1 -> 2028 | N4: =M4+1 -> 2029 | O4: =N4+1 -> 2030 | P4: =O4+1 -> 2031 | Q4: =P4+1 -> 2032 | R4: =Q4+1 -> 2033 | ... X4: =W4+1 -> 2039
B6: Revenue (linked from Revenue sheet)
B7: VOCO Hotel | D7: 1
C8: Rooms revenue | H8: =SUM(J8:X8) -> 4770729.1 | J8: =Revenue!L316 -> 0 | K8: =Revenue!M316 -> 265571.24 | L8: =Revenue!N316 -> 275698.24 | M8: =Revenue!O316 -> 285825.24 | N8: =Revenue!P316 -> 297018.24 | O8: =Revenue!Q316 -> 309646.24 | P8: =Revenue!R316 -> 328470.82 | Q8: =Revenue!S316 -> 338324.95 | ... X8: =Revenue!Z316 -> 416097.01
C9: F&B revenue | H9: =SUM(J9:X9) -> 872604.83 | J9: =Revenue!L317 -> 0 | K9: =Revenue!M317 -> 48580.106 | L9: =Revenue!N317 -> 50432.606 | M9: =Revenue!O317 -> 52285.106 | N9: =Revenue!P317 -> 54332.606 | O9: =Revenue!Q317 -> 56642.606 | P9: =Revenue!R317 -> 60077.313 | Q9: =Revenue!S317 -> 61879.632 | ... X9: =Revenue!Z317 -> 76104.143
C10: Other Revenue | H10: =SUM(J10:X10) -> 170994.88 | J10: =Revenue!L318 -> 0 | K10: =Revenue!M318 -> 9716.021 | L10: =Revenue!N318 -> 10086.521 | M10: =Revenue!O318 -> 10457.021 | N10: =Revenue!P318 -> 10866.521 | O10: =Revenue!Q318 -> 11328.521 | P10: =Revenue!R318 -> 11668.377 | Q10: =Revenue!S318 -> 12018.428 | ... X10: =Revenue!Z318 -> 14781.15
B11: Total VOCO Revenue | H11: =SUM(J11:X11) -> 5814328.9 | J11: =SUM(J8:J10) -> 0 | K11: =SUM(K8:K10) -> 323867.37 | L11: =SUM(L8:L10) -> 336217.37 | M11: =SUM(M8:M10) -> 348567.37 | N11: =SUM(N8:N10) -> 362217.37 | O11: =SUM(O8:O10) -> 377617.37 | P11: =SUM(P8:P10) -> 400216.51 | Q11: =SUM(Q8:Q10) -> 412223.01 | ... X11: =SUM(X8:X10) -> 506982.3
B12: Residential Tower 01 (Hotel) | D12: 2
C13: Units (Rooms) revenue | H13: =SUM(J13:X13) -> 924446.76 | J13: =Revenue!L265 -> 0 | K13: =Revenue!M265 -> 0 | L13: =Revenue!N265 -> 0 | M13: =Revenue!O265 -> 0 | N13: =Revenue!P265 -> 46375.6 | O13: =Revenue!Q265 -> 55088.797 | P13: =Revenue!R265 -> 72542.88 | Q13: =Revenue!S265 -> 84567.544 | ... X13: =Revenue!Z265 -> 103723.24
C14: F&B revenue | H14: =SUM(J14:X14) -> 73955.741 | J14: =Revenue!L266 -> 0 | K14: =Revenue!M266 -> 0 | L14: =Revenue!N266 -> 0 | M14: =Revenue!O266 -> 0 | N14: =Revenue!P266 -> 3710.048 | O14: =Revenue!Q266 -> 4407.1037 | P14: =Revenue!R266 -> 5803.4304 | Q14: =Revenue!S266 -> 6765.4035 | ... X14: =Revenue!Z266 -> 8297.8591
B15: Total Tower 01 Revenue | H15: =SUM(J15:X15) -> 998402.5 | J15: =SUM(J13:J14) -> 0 | K15: =SUM(K13:K14) -> 0 | L15: =SUM(L13:L14) -> 0 | M15: =SUM(M13:M14) -> 0 | N15: =SUM(N13:N14) -> 50085.648 | O15: =SUM(O13:O14) -> 59495.9 | P15: =SUM(P13:P14) -> 78346.31 | Q15: =SUM(Q13:Q14) -> 91332.947 | ... X15: =SUM(X13:X14) -> 112021.1
B16: Hotel 01 - 336 Keys | D16: 2
C17: Units (Rooms) revenue | H17: =SUM(J17:X17) -> 746343.36 | J17: =Revenue!L296 -> 0 | K17: =Revenue!M296 -> 0 | L17: =Revenue!N296 -> 0 | M17: =Revenue!O296 -> 0 | N17: =Revenue!P296 -> 46585.935 | O17: =Revenue!Q296 -> 52553.372 | P17: =Revenue!R296 -> 59425.296 | Q17: =Revenue!S296 -> 66237.194 | ... X17: =Revenue!Z296 -> 81240.816
C18: F&B revenue | H18: =SUM(J18:X18) -> 223903.01 | J18: =Revenue!L297 -> 0 | K18: =Revenue!M297 -> 0 | L18: =Revenue!N297 -> 0 | M18: =Revenue!O297 -> 0 | N18: =Revenue!P297 -> 13975.781 | O18: =Revenue!Q297 -> 15766.011 | P18: =Revenue!R297 -> 17827.589 | Q18: =Revenue!S297 -> 19871.158 | ... X18: =Revenue!Z297 -> 24372.245
B19: Total Hotel 01 Revenue | H19: =SUM(J19:X19) -> 970246.36 | J19: =SUM(J17:J18) -> 0 | K19: =SUM(K17:K18) -> 0 | L19: =SUM(L17:L18) -> 0 | M19: =SUM(M17:M18) -> 0 | N19: =SUM(N17:N18) -> 60561.716 | O19: =SUM(O17:O18) -> 68319.383 | P19: =SUM(P17:P18) -> 77252.885 | Q19: =SUM(Q17:Q18) -> 86108.352 | ... X19: =SUM(X17:X18) -> 105613.06
C20: Support Retail (Phase 2) | D20: 2 | H20: =SUM(J20:X20) -> 220121.29 | J20: =Revenue!L324 -> 0 | K20: =Revenue!M324 -> 0 | L20: =Revenue!N324 -> 0 | M20: =Revenue!O324 -> 0 | N20: =Revenue!P324 -> 9598.2878 | O20: =Revenue!Q324 -> 13117.66 | P20: =Revenue!R324 -> 16807.002 | Q20: =Revenue!S324 -> 20672.612 | ... X20: =Revenue!Z324 -> 24573.24
C21: Support Retail (Phase 3) | D21: 3 | H21: =SUM(J21:X21) -> 115889.21 | J21: =Revenue!L325 -> 0 | K21: =Revenue!M325 -> 0 | L21: =Revenue!N325 -> 0 | M21: =Revenue!O325 -> 0 | N21: =Revenue!P325 -> 5053.296 | O21: =Revenue!Q325 -> 6906.1712 | P21: =Revenue!R325 -> 8848.5318 | Q21: =Revenue!S325 -> 10883.694 | ... X21: =Revenue!Z325 -> 12937.292
B22: Total Revenue (operated) | H22: =SUM(J22:X22) -> 8118988.2 | J22: =J11+J15+J19+J20+J21 -> 0 | K22: =K11+K15+K19+K20+K21 -> 323867.37 | L22: =L11+L15+L19+L20+L21 -> 336217.37 | M22: =M11+M15+M19+M20+M21 -> 348567.37 | N22: =N11+N15+N19+N20+N21 -> 487516.32 | O22: =O11+O15+O19+O20+O21 -> 525456.48 | P22: =P11+P15+P19+P20+P21 -> 581471.24 | Q22: =Q11+Q15+Q19+Q20+Q21 -> 621220.61 | ... X22: =X11+X15+X19+X20+X21 -> 762126.99
B24: Operating Costs
C26: VOCO Hotel - Operating Expenses | F26: % basis | G26: Rate | H26: Total
C27: NOP % (source: Phase 1 Projected Revenues) | F27: % of Rev | G27: =AVERAGE(J27:X27) -> 0.49174251 | J27: 0 | K27: 0.51804496 | L27: 0.51803861 | M27: 0.50315324 | N27: 0.51733738 | O27: 0.5315634 | P27: 0.532 | Q27: 0.532 | R27: 0.532 | S27: 0.532 | T27: 0.532 | U27: 0.532 | V27: 0.532 | W27: 0.532 | X27: 0.532
C28: Operating Cost = -NOP% × Total VOCO Revenue | H28: =SUM(J28:X28) -> -3068478.3 | J28: =-J27*J11 -> 0 | K28: =-K27*K11 -> -167777.86 | L28: =-L27*L11 -> -174173.58 | M28: =-M27*M11 -> -175382.8 | N28: =-N27*N11 -> -187388.59 | O28: =-O27*O11 -> -200727.57 | P28: =-P27*P11 -> -212915.18 | Q28: =-Q27*Q11 -> -219302.64 | ... X28: =-X27*X11 -> -269714.58
C29: Total VOCO Operating Costs | H29: =SUM(J29:X29) -> -3068478.3 | J29: =J28 -> 0 | K29: =K28 -> -167777.86 | L29: =L28 -> -174173.58 | M29: =M28 -> -175382.8 | N29: =N28 -> -187388.59 | O29: =O28 -> -200727.57 | P29: =P28 -> -212915.18 | Q29: =Q28 -> -219302.64 | ... X29: =X28 -> -269714.58
C31: Residential Tower 01 - Operating Expenses | F31: % basis | G31: Rate | H31: Total
C32: Departmental Expenses
C33: Units (Rooms) expense | F33: % Units rev | G33: 0 | H33: =SUM(J33:X33) -> 0 | J33: =-$G$33*J13 -> 0 | K33: =-$G$33*K13 -> 0 | L33: =-$G$33*L13 -> 0 | M33: =-$G$33*M13 -> 0 | N33: =-$G$33*N13 -> 0 | O33: =-$G$33*O13 -> 0 | P33: =-$G$33*P13 -> 0 | Q33: =-$G$33*Q13 -> 0 | ... X33: =-$G$33*X13 -> 0
C34: F&B expense | F34: % F&B rev | G34: 0.67 | H34: =SUM(J34:X34) -> -49550.346 | J34: =-$G$34*J14 -> 0 | K34: =-$G$34*K14 -> 0 | L34: =-$G$34*L14 -> 0 | M34: =-$G$34*M14 -> 0 | N34: =-$G$34*N14 -> -2485.7322 | O34: =-$G$34*O14 -> -2952.7595 | P34: =-$G$34*P14 -> -3888.2984 | Q34: =-$G$34*Q14 -> -4532.8203 | ... X34: =-$G$34*X14 -> -5559.5656
C35: Undistributed Expenses
C36: G&A | F36: % Units rev | G36: 0.75 | H36: =SUM(J36:X36) -> -693335.07 | J36: =-$G$36*J13 -> 0 | K36: =-$G$36*K13 -> 0 | L36: =-$G$36*L13 -> 0 | M36: =-$G$36*M13 -> 0 | N36: =-$G$36*N13 -> -34781.7 | O36: =-$G$36*O13 -> -41316.598 | P36: =-$G$36*P13 -> -54407.16 | Q36: =-$G$36*Q13 -> -63425.658 | ... X36: =-$G$36*X13 -> -77792.429
C37: Total Tower 01 OpEx | H37: =SUM(J37:X37) -> -742885.42 | J37: =SUM(J33:J34)+J36 -> 0 | K37: =SUM(K33:K34)+K36 -> 0 | L37: =SUM(L33:L34)+L36 -> 0 | M37: =SUM(M33:M34)+M36 -> 0 | N37: =SUM(N33:N34)+N36 -> -37267.432 | O37: =SUM(O33:O34)+O36 -> -44269.357 | P37: =SUM(P33:P34)+P36 -> -58295.458 | Q37: =SUM(Q33:Q34)+Q36 -> -67958.478 | ... X37: =SUM(X33:X34)+X36 -> -83351.995
C39: Hotel 01 (336 Keys) - Operating Expenses | F39: % basis | G39: Rate
C40: Departmental Expenses
C41: Units (Rooms) expense | F41: % Units rev | G41: 0.14 | H41: =SUM(J41:X41) -> -104488.07 | J41: =-$G$41*J17 -> 0 | K41: =-$G$41*K17 -> 0 | L41: =-$G$41*L17 -> 0 | M41: =-$G$41*M17 -> 0 | N41: =-$G$41*N17 -> -6522.0309 | O41: =-$G$41*O17 -> -7357.472 | P41: =-$G$41*P17 -> -8319.5415 | Q41: =-$G$41*Q17 -> -9273.2071 | ... X41: =-$G$41*X17 -> -11373.714
C42: F&B expense | F42: % F&B rev | G42: 0.65 | H42: =SUM(J42:X42) -> -145536.95 | J42: =-$G$42*J18 -> 0 | K42: =-$G$42*K18 -> 0 | L42: =-$G$42*L18 -> 0 | M42: =-$G$42*M18 -> 0 | N42: =-$G$42*N18 -> -9084.2574 | O42: =-$G$42*O18 -> -10247.907 | P42: =-$G$42*P18 -> -11587.933 | Q42: =-$G$42*Q18 -> -12916.253 | ... X42: =-$G$42*X18 -> -15841.959
C43: Undistributed Expenses
C44: G&A | F44: % total rev | G44: 0.09 | H44: =SUM(J44:X44) -> -87322.173 | J44: =-$G$44*J19 -> 0 | K44: =-$G$44*K19 -> 0 | L44: =-$G$44*L19 -> 0 | M44: =-$G$44*M19 -> 0 | N44: =-$G$44*N19 -> -5450.5544 | O44: =-$G$44*O19 -> -6148.7445 | P44: =-$G$44*P19 -> -6952.7597 | Q44: =-$G$44*Q19 -> -7749.7517 | ... X44: =-$G$44*X19 -> -9505.1755
C45: Sales & Marketing | F45: % total rev | G45: 0.05 | H45: =SUM(J45:X45) -> -48512.318 | J45: =-$G$45*J19 -> 0 | K45: =-$G$45*K19 -> 0 | L45: =-$G$45*L19 -> 0 | M45: =-$G$45*M19 -> 0 | N45: =-$G$45*N19 -> -3028.0858 | O45: =-$G$45*O19 -> -3415.9692 | P45: =-$G$45*P19 -> -3862.6443 | Q45: =-$G$45*Q19 -> -4305.4176 | ... X45: =-$G$45*X19 -> -5280.653
...

Sheet Capex
B1: MAAD RESIDENTIAL WITH HOTEL - CAPEX
B2: All figures in SAR'000
B3: Asset cost stack (5 assets, sub-units, land), depreciation schedule and variance vs main MAAD model.
B4: Capex Asset & Sub-Asset Cost Stack with Cash Flow Allocation | D4: Phase | G4: Driver | H4: Quantity / Base | I4: Rate | L4: Total | M4: 2026 | N4: 2027 | O4: 2028 | P4: 2029 | Q4: 2030 | R4: 2031 | S4: =R4+1 -> 2032 | T4: =S4+1 -> 2033 | U4: =T4+1 -> 2034 | V4: =U4+1 -> 2035 | W4: =V4+1 -> 2036 | X4: =W4+1 -> 2037 | Y4: =X4+1 -> 2038 | Z4: =Y4+1 -> 2039
B6: Cash Flow Allocation - by Year (% of category total)
C8: Branded Apartments T2 & T3 - Allocation %
C9: Land | K9: =SUM(L9:R9) -> 1 | M9: =CHOOSE(CF!$G$1,'Capex Allocation'!H9,'Capex Allocation'!H71) -> 1 | N9: =CHOOSE(CF!$G$1,'Capex Allocation'!I9,'Capex Allocation'!I71) -> 0 | O9: =CHOOSE(CF!$G$1,'Capex Allocation'!J9,'Capex Allocation'!J71) -> 0 | P9: =CHOOSE(CF!$G$1,'Capex Allocation'!K9,'Capex Allocation'!K71) -> 0 | Q9: =CHOOSE(CF!$G$1,'Capex Allocation'!L9,'Capex Allocation'!L71) -> 0 | R9: =CHOOSE(CF!$G$1,'Capex Allocation'!M9,'Capex Allocation'!M71) -> 0 | S9: =CHOOSE(CF!$G$1,'Capex Allocation'!N9,'Capex Allocation'!N71) -> 0 | T9: =CHOOSE(CF!$G$1,'Capex Allocation'!O9,'Capex Allocation'!O71) -> 0 | ... Z9: =CHOOSE(CF!$G$1,'Capex Allocation'!U9,'Capex Allocation'!U71) -> 0
C10: Construction (BUA + Parking) | K10: =SUM(L10:R10) -> 1 | M10: =CHOOSE(CF!$G$1,'Capex Allocation'!H10,'Capex Allocation'!H72) -> 0.1 | N10: =CHOOSE(CF!$G$1,'Capex Allocation'!I10,'Capex Allocation'!I72) -> 0.25 | O10: =CHOOSE(CF!$G$1,'Capex Allocation'!J10,'Capex Allocation'!J72) -> 0.3 | P10: =CHOOSE(CF!$G$1,'Capex Allocation'!K10,'Capex Allocation'!K72) -> 0.25 | Q10: =CHOOSE(CF!$G$1,'Capex Allocation'!L10,'Capex Allocation'!L72) -> 0.1 | R10: =CHOOSE(CF!$G$1,'Capex Allocation'!M10,'Capex Allocation'!M72) -> 0 | S10: =CHOOSE(CF!$G$1,'Capex Allocation'!N10,'Capex Allocation'!N72) -> 0 | T10: =CHOOSE(CF!$G$1,'Capex Allocation'!O10,'Capex Allocation'!O72) -> 0 | ... Z10: =CHOOSE(CF!$G$1,'Capex Allocation'!U10,'Capex Allocation'!U72) -> 0
C11: Infrastructure | K11: =SUM(L11:R11) -> 1 | M11: =CHOOSE(CF!$G$1,'Capex Allocation'!H11,'Capex Allocation'!H73) -> 0.1 | N11: =CHOOSE(CF!$G$1,'Capex Allocation'!I11,'Capex Allocation'!I73) -> 0.25 | O11: =CHOOSE(CF!$G$1,'Capex Allocation'!J11,'Capex Allocation'!J73) -> 0.3 | P11: =CHOOSE(CF!$G$1,'Capex Allocation'!K11,'Capex Allocation'!K73) -> 0.25 | Q11: =CHOOSE(CF!$G$1,'Capex Allocation'!L11,'Capex Allocation'!L73) -> 0.1 | R11: =CHOOSE(CF!$G$1,'Capex Allocation'!M11,'Capex Allocation'!M73) -> 0 | S11: =CHOOSE(CF!$G$1,'Capex Allocation'!N11,'Capex Allocation'!N73) -> 0 | T11: =CHOOSE(CF!$G$1,'Capex Allocation'!O11,'Capex Allocation'!O73) -> 0 | ... Z11: =CHOOSE(CF!$G$1,'Capex Allocation'!U11,'Capex Allocation'!U73) -> 0
C12: Landscaping | K12: =SUM(L12:R12) -> 1 | M12: =CHOOSE(CF!$G$1,'Capex Allocation'!H12,'Capex Allocation'!H74) -> 0.1 | N12: =CHOOSE(CF!$G$1,'Capex Allocation'!I12,'Capex Allocation'!I74) -> 0.25 | O12: =CHOOSE(CF!$G$1,'Capex Allocation'!J12,'Capex Allocation'!J74) -> 0.3 | P12: =CHOOSE(CF!$G$1,'Capex Allocation'!K12,'Capex Allocation'!K74) -> 0.25 | Q12: =CHOOSE(CF!$G$1,'Capex Allocation'!L12,'Capex Allocation'!L74) -> 0.1 | R12: =CHOOSE(CF!$G$1,'Capex Allocation'!M12,'Capex Allocation'!M74) -> 0 | S12: =CHOOSE(CF!$G$1,'Capex Allocation'!N12,'Capex Allocation'!N74) -> 0 | T12: =CHOOSE(CF!$G$1,'Capex Allocation'!O12,'Capex Allocation'!O74) -> 0 | ... Z12: =CHOOSE(CF!$G$1,'Capex Allocation'!U12,'Capex Allocation'!U74) -> 0
C13: Pre-operating | K13: =SUM(L13:R13) -> 1 | M13: =CHOOSE(CF!$G$1,'Capex Allocation'!H13,'Capex Allocation'!H75) -> 0.1 | N13: =CHOOSE(CF!$G$1,'Capex Allocation'!I13,'Capex Allocation'!I75) -> 0.25 | O13: =CHOOSE(CF!$G$1,'Capex Allocation'!J13,'Capex Allocation'!J75) -> 0.3 | P13: =CHOOSE(CF!$G$1,'Capex Allocation'!K13,'Capex Allocation'!K75) -> 0.25 | Q13: =CHOOSE(CF!$G$1,'Capex Allocation'!L13,'Capex Allocation'!L75) -> 0.1 | R13: =CHOOSE(CF!$G$1,'Capex Allocation'!M13,'Capex Allocation'!M75) -> 0 | S13: =CHOOSE(CF!$G$1,'Capex Allocation'!N13,'Capex Allocation'!N75) -> 0 | T13: =CHOOSE(CF!$G$1,'Capex Allocation'!O13,'Capex Allocation'!O75) -> 0 | ... Z13: =CHOOSE(CF!$G$1,'Capex Allocation'!U13,'Capex Allocation'!U75) -> 0
C14: Professional fee | K14: =SUM(L14:R14) -> 1 | M14: =CHOOSE(CF!$G$1,'Capex Allocation'!H14,'Capex Allocation'!H76) -> 0.1 | N14: =CHOOSE(CF!$G$1,'Capex Allocation'!I14,'Capex Allocation'!I76) -> 0.25 | O14: =CHOOSE(CF!$G$1,'Capex Allocation'!J14,'Capex Allocation'!J76) -> 0.3 | P14: =CHOOSE(CF!$G$1,'Capex Allocation'!K14,'Capex Allocation'!K76) -> 0.25 | Q14: =CHOOSE(CF!$G$1,'Capex Allocation'!L14,'Capex Allocation'!L76) -> 0.1 | R14: =CHOOSE(CF!$G$1,'Capex Allocation'!M14,'Capex Allocation'!M76) -> 0 | S14: =CHOOSE(CF!$G$1,'Capex Allocation'!N14,'Capex Allocation'!N76) -> 0 | T14: =CHOOSE(CF!$G$1,'Capex Allocation'!O14,'Capex Allocation'!O76) -> 0 | ... Z14: =CHOOSE(CF!$G$1,'Capex Allocation'!U14,'Capex Allocation'!U76) -> 0
C15: Commission | K15: =SUM(L15:R15) -> 1 | M15: =CHOOSE(CF!$G$1,'Capex Allocation'!H15,'Capex Allocation'!H77) -> 0.1 | N15: =CHOOSE(CF!$G$1,'Capex Allocation'!I15,'Capex Allocation'!I77) -> 0.25 | O15: =CHOOSE(CF!$G$1,'Capex Allocation'!J15,'Capex Allocation'!J77) -> 0.3 | P15: =CHOOSE(CF!$G$1,'Capex Allocation'!K15,'Capex Allocation'!K77) -> 0.25 | Q15: =CHOOSE(CF!$G$1,'Capex Allocation'!L15,'Capex Allocation'!L77) -> 0.1 | R15: =CHOOSE(CF!$G$1,'Capex Allocation'!M15,'Capex Allocation'!M77) -> 0 | S15: =CHOOSE(CF!$G$1,'Capex Allocation'!N15,'Capex Allocation'!N77) -> 0 | T15: =CHOOSE(CF!$G$1,'Capex Allocation'!O15,'Capex Allocation'!O77) -> 0 | ... Z15: =CHOOSE(CF!$G$1,'Capex Allocation'!U15,'Capex Allocation'!U77) -> 0
C16: Contingency | K16: =SUM(L16:R16) -> 1 | M16: =CHOOSE(CF!$G$1,'Capex Allocation'!H16,'Capex Allocation'!H78) -> 0.1 | N16: =CHOOSE(CF!$G$1,'Capex Allocation'!I16,'Capex Allocation'!I78) -> 0.25 | O16: =CHOOSE(CF!$G$1,'Capex Allocation'!J16,'Capex Allocation'!J78) -> 0.3 | P16: =CHOOSE(CF!$G$1,'Capex Allocation'!K16,'Capex Allocation'!K78) -> 0.25 | Q16: =CHOOSE(CF!$G$1,'Capex Allocation'!L16,'Capex Allocation'!L78) -> 0.1 | R16: =CHOOSE(CF!$G$1,'Capex Allocation'!M16,'Capex Allocation'!M78) -> 0 | S16: =CHOOSE(CF!$G$1,'Capex Allocation'!N16,'Capex Allocation'!N78) -> 0 | T16: =CHOOSE(CF!$G$1,'Capex Allocation'!O16,'Capex Allocation'!O78) -> 0 | ... Z16: =CHOOSE(CF!$G$1,'Capex Allocation'!U16,'Capex Allocation'!U78) -> 0
C17: Check (=100%)
C19: Branded Apartments T4 & T5 - Allocation %
C20: Land | K20: =SUM(L20:R20) -> 1 | M20: =CHOOSE(CF!$G$1,'Capex Allocation'!H19,'Capex Allocation'!H81) -> 1 | N20: =CHOOSE(CF!$G$1,'Capex Allocation'!I19,'Capex Allocation'!I81) -> 0 | O20: =CHOOSE(CF!$G$1,'Capex Allocation'!J19,'Capex Allocation'!J81) -> 0 | P20: =CHOOSE(CF!$G$1,'Capex Allocation'!K19,'Capex Allocation'!K81) -> 0 | Q20: =CHOOSE(CF!$G$1,'Capex Allocation'!L19,'Capex Allocation'!L81) -> 0 | R20: =CHOOSE(CF!$G$1,'Capex Allocation'!M19,'Capex Allocation'!M81) -> 0 | S20: =CHOOSE(CF!$G$1,'Capex Allocation'!N19,'Capex Allocation'!N81) -> 0 | T20: =CHOOSE(CF!$G$1,'Capex Allocation'!O19,'Capex Allocation'!O81) -> 0 | ... Z20: =CHOOSE(CF!$G$1,'Capex Allocation'!U19,'Capex Allocation'!U81) -> 0
C21: Construction (BUA + Parking) | K21: =SUM(L21:R21) -> 1 | M21: =CHOOSE(CF!$G$1,'Capex Allocation'!H20,'Capex Allocation'!H82) -> 0.1 | N21: =CHOOSE(CF!$G$1,'Capex Allocation'!I20,'Capex Allocation'!I82) -> 0.1 | O21: =CHOOSE(CF!$G$1,'Capex Allocation'!J20,'Capex Allocation'!J82) -> 0.25 | P21: =CHOOSE(CF!$G$1,'Capex Allocation'!K20,'Capex Allocation'!K82) -> 0.25 | Q21: =CHOOSE(CF!$G$1,'Capex Allocation'!L20,'Capex Allocation'!L82) -> 0.25 | R21: =CHOOSE(CF!$G$1,'Capex Allocation'!M20,'Capex Allocation'!M82) -> 0.05 | S21: =CHOOSE(CF!$G$1,'Capex Allocation'!N20,'Capex Allocation'!N82) -> 0 | T21: =CHOOSE(CF!$G$1,'Capex Allocation'!O20,'Capex Allocation'!O82) -> 0 | ... Z21: =CHOOSE(CF!$G$1,'Capex Allocation'!U20,'Capex Allocation'!U82) -> 0
C22: Infrastructure | K22: =SUM(L22:R22) -> 1 | M22: =CHOOSE(CF!$G$1,'Capex Allocation'!H21,'Capex Allocation'!H83) -> 0.1 | N22: =CHOOSE(CF!$G$1,'Capex Allocation'!I21,'Capex Allocation'!I83) -> 0.1 | O22: =CHOOSE(CF!$G$1,'Capex Allocation'!J21,'Capex Allocation'!J83) -> 0.25 | P22: =CHOOSE(CF!$G$1,'Capex Allocation'!K21,'Capex Allocation'!K83) -> 0.25 | Q22: =CHOOSE(CF!$G$1,'Capex Allocation'!L21,'Capex Allocation'!L83) -> 0.25 | R22: =CHOOSE(CF!$G$1,'Capex Allocation'!M21,'Capex Allocation'!M83) -> 0.05 | S22: =CHOOSE(CF!$G$1,'Capex Allocation'!N21,'Capex Allocation'!N83) -> 0 | T22: =CHOOSE(CF!$G$1,'Capex Allocation'!O21,'Capex Allocation'!O83) -> 0 | ... Z22: =CHOOSE(CF!$G$1,'Capex Allocation'!U21,'Capex Allocation'!U83) -> 0
C23: Landscaping | K23: =SUM(L23:R23) -> 1 | M23: =CHOOSE(CF!$G$1,'Capex Allocation'!H22,'Capex Allocation'!H84) -> 0.1 | N23: =CHOOSE(CF!$G$1,'Capex Allocation'!I22,'Capex Allocation'!I84) -> 0.1 | O23: =CHOOSE(CF!$G$1,'Capex Allocation'!J22,'Capex Allocation'!J84) -> 0.25 | P23: =CHOOSE(CF!$G$1,'Capex Allocation'!K22,'Capex Allocation'!K84) -> 0.25 | Q23: =CHOOSE(CF!$G$1,'Capex Allocation'!L22,'Capex Allocation'!L84) -> 0.25 | R23: =CHOOSE(CF!$G$1,'Capex Allocation'!M22,'Capex Allocation'!M84) -> 0.05 | S23: =CHOOSE(CF!$G$1,'Capex Allocation'!N22,'Capex Allocation'!N84) -> 0 | T23: =CHOOSE(CF!$G$1,'Capex Allocation'!O22,'Capex Allocation'!O84) -> 0 | ... Z23: =CHOOSE(CF!$G$1,'Capex Allocation'!U22,'Capex Allocation'!U84) -> 0
C24: Pre-operating | K24: =SUM(L24:R24) -> 1 | M24: =CHOOSE(CF!$G$1,'Capex Allocation'!H23,'Capex Allocation'!H85) -> 0.1 | N24: =CHOOSE(CF!$G$1,'Capex Allocation'!I23,'Capex Allocation'!I85) -> 0.1 | O24: =CHOOSE(CF!$G$1,'Capex Allocation'!J23,'Capex Allocation'!J85) -> 0.25 | P24: =CHOOSE(CF!$G$1,'Capex Allocation'!K23,'Capex Allocation'!K85) -> 0.25 | Q24: =CHOOSE(CF!$G$1,'Capex Allocation'!L23,'Capex Allocation'!L85) -> 0.25 | R24: =CHOOSE(CF!$G$1,'Capex Allocation'!M23,'Capex Allocation'!M85) -> 0.05 | S24: =CHOOSE(CF!$G$1,'Capex Allocation'!N23,'Capex Allocation'!N85) -> 0 | T24: =CHOOSE(CF!$G$1,'Capex Allocation'!O23,'Capex Allocation'!O85) -> 0 | ... Z24: =CHOOSE(CF!$G$1,'Capex Allocation'!U23,'Capex Allocation'!U85) -> 0
C25: Professional fee | K25: =SUM(L25:R25) -> 1 | M25: =CHOOSE(CF!$G$1,'Capex Allocation'!H24,'Capex Allocation'!H86) -> 0.1 | N25: =CHOOSE(CF!$G$1,'Capex Allocation'!I24,'Capex Allocation'!I86) -> 0.1 | O25: =CHOOSE(CF!$G$1,'Capex Allocation'!J24,'Capex Allocation'!J86) -> 0.25 | P25: =CHOOSE(CF!$G$1,'Capex Allocation'!K24,'Capex Allocation'!K86) -> 0.25 | Q25: =CHOOSE(CF!$G$1,'Capex Allocation'!L24,'Capex Allocation'!L86) -> 0.25 | R25: =CHOOSE(CF!$G$1,'Capex Allocation'!M24,'Capex Allocation'!M86) -> 0.05 | S25: =CHOOSE(CF!$G$1,'Capex Allocation'!N24,'Capex Allocation'!N86) -> 0 | T25: =CHOOSE(CF!$G$1,'Capex Allocation'!O24,'Capex Allocation'!O86) -> 0 | ... Z25: =CHOOSE(CF!$G$1,'Capex Allocation'!U24,'Capex Allocation'!U86) -> 0
C26: Commission | K26: =SUM(L26:R26) -> 1 | M26: =CHOOSE(CF!$G$1,'Capex Allocation'!H25,'Capex Allocation'!H87) -> 0.1 | N26: =CHOOSE(CF!$G$1,'Capex Allocation'!I25,'Capex Allocation'!I87) -> 0.1 | O26: =CHOOSE(CF!$G$1,'Capex Allocation'!J25,'Capex Allocation'!J87) -> 0.25 | P26: =CHOOSE(CF!$G$1,'Capex Allocation'!K25,'Capex Allocation'!K87) -> 0.25 | Q26: =CHOOSE(CF!$G$1,'Capex Allocation'!L25,'Capex Allocation'!L87) -> 0.25 | R26: =CHOOSE(CF!$G$1,'Capex Allocation'!M25,'Capex Allocation'!M87) -> 0.05 | S26: =CHOOSE(CF!$G$1,'Capex Allocation'!N25,'Capex Allocation'!N87) -> 0 | T26: =CHOOSE(CF!$G$1,'Capex Allocation'!O25,'Capex Allocation'!O87) -> 0 | ... Z26: =CHOOSE(CF!$G$1,'Capex Allocation'!U25,'Capex Allocation'!U87) -> 0
C27: Contingency | K27: =SUM(L27:R27) -> 1 | M27: =CHOOSE(CF!$G$1,'Capex Allocation'!H26,'Capex Allocation'!H88) -> 0.1 | N27: =CHOOSE(CF!$G$1,'Capex Allocation'!I26,'Capex Allocation'!I88) -> 0.1 | O27: =CHOOSE(CF!$G$1,'Capex Allocation'!J26,'Capex Allocation'!J88) -> 0.25 | P27: =CHOOSE(CF!$G$1,'Capex Allocation'!K26,'Capex Allocation'!K88) -> 0.25 | Q27: =CHOOSE(CF!$G$1,'Capex Allocation'!L26,'Capex Allocation'!L88) -> 0.25 | R27: =CHOOSE(CF!$G$1,'Capex Allocation'!M26,'Capex Allocation'!M88) -> 0.05 | S27: =CHOOSE(CF!$G$1,'Capex Allocation'!N26,'Capex Allocation'!N88) -> 0 | T27: =CHOOSE(CF!$G$1,'Capex Allocation'!O26,'Capex Allocation'!O88) -> 0 | ... Z27: =CHOOSE(CF!$G$1,'Capex Allocation'!U26,'Capex Allocation'!U88) -> 0
C28: Check (=100%)
C30: Residential Tower 01 - Allocation %
C31: Land | K31: =SUM(L31:R31) -> 1 | M31: =CHOOSE(CF!$G$1,'Capex Allocation'!H29,'Capex Allocation'!H91) -> 1 | N31: =CHOOSE(CF!$G$1,'Capex Allocation'!I29,'Capex Allocation'!I91) -> 0 | O31: =CHOOSE(CF!$G$1,'Capex Allocation'!J29,'Capex Allocation'!J91) -> 0 | P31: =CHOOSE(CF!$G$1,'Capex Allocation'!K29,'Capex Allocation'!K91) -> 0 | Q31: =CHOOSE(CF!$G$1,'Capex Allocation'!L29,'Capex Allocation'!L91) -> 0 | R31: =CHOOSE(CF!$G$1,'Capex Allocation'!M29,'Capex Allocation'!M91) -> 0 | S31: =CHOOSE(CF!$G$1,'Capex Allocation'!N29,'Capex Allocation'!N91) -> 0 | T31: =CHOOSE(CF!$G$1,'Capex Allocation'!O29,'Capex Allocation'!O91) -> 0 | ... Z31: =CHOOSE(CF!$G$1,'Capex Allocation'!U29,'Capex Allocation'!U91) -> 0
C32: Construction (BUA + Parking) | K32: =SUM(L32:R32) -> 1 | M32: =CHOOSE(CF!$G$1,'Capex Allocation'!H30,'Capex Allocation'!H92) -> 0.1 | N32: =CHOOSE(CF!$G$1,'Capex Allocation'!I30,'Capex Allocation'!I92) -> 0.25 | O32: =CHOOSE(CF!$G$1,'Capex Allocation'!J30,'Capex Allocation'!J92) -> 0.3 | P32: =CHOOSE(CF!$G$1,'Capex Allocation'!K30,'Capex Allocation'!K92) -> 0.25 | Q32: =CHOOSE(CF!$G$1,'Capex Allocation'!L30,'Capex Allocation'!L92) -> 0.1 | R32: =CHOOSE(CF!$G$1,'Capex Allocation'!M30,'Capex Allocation'!M92) -> 0 | S32: =CHOOSE(CF!$G$1,'Capex Allocation'!N30,'Capex Allocation'!N92) -> 0 | T32: =CHOOSE(CF!$G$1,'Capex Allocation'!O30,'Capex Allocation'!O92) -> 0 | ... Z32: =CHOOSE(CF!$G$1,'Capex Allocation'!U30,'Capex Allocation'!U92) -> 0
C33: Infrastructure | K33: =SUM(L33:R33) -> 1 | M33: =CHOOSE(CF!$G$1,'Capex Allocation'!H31,'Capex Allocation'!H93) -> 0.1 | N33: =CHOOSE(CF!$G$1,'Capex Allocation'!I31,'Capex Allocation'!I93) -> 0.25 | O33: =CHOOSE(CF!$G$1,'Capex Allocation'!J31,'Capex Allocation'!J93) -> 0.3 | P33: =CHOOSE(CF!$G$1,'Capex Allocation'!K31,'Capex Allocation'!K93) -> 0.25 | Q33: =CHOOSE(CF!$G$1,'Capex Allocation'!L31,'Capex Allocation'!L93) -> 0.1 | R33: =CHOOSE(CF!$G$1,'Capex Allocation'!M31,'Capex Allocation'!M93) -> 0 | S33: =CHOOSE(CF!$G$1,'Capex Allocation'!N31,'Capex Allocation'!N93) -> 0 | T33: =CHOOSE(CF!$G$1,'Capex Allocation'!O31,'Capex Allocation'!O93) -> 0 | ... Z33: =CHOOSE(CF!$G$1,'Capex Allocation'!U31,'Capex Allocation'!U93) -> 0
C34: Landscaping | K34: =SUM(L34:R34) -> 1 | M34: =CHOOSE(CF!$G$1,'Capex Allocation'!H32,'Capex Allocation'!H94) -> 0.1 | N34: =CHOOSE(CF!$G$1,'Capex Allocation'!I32,'Capex Allocation'!I94) -> 0.25 | O34: =CHOOSE(CF!$G$1,'Capex Allocation'!J32,'Capex Allocation'!J94) -> 0.3 | P34: =CHOOSE(CF!$G$1,'Capex Allocation'!K32,'Capex Allocation'!K94) -> 0.25 | Q34: =CHOOSE(CF!$G$1,'Capex Allocation'!L32,'Capex Allocation'!L94) -> 0.1 | R34: =CHOOSE(CF!$G$1,'Capex Allocation'!M32,'Capex Allocation'!M94) -> 0 | S34: =CHOOSE(CF!$G$1,'Capex Allocation'!N32,'Capex Allocation'!N94) -> 0 | T34: =CHOOSE(CF!$G$1,'Capex Allocation'!O32,'Capex Allocation'!O94) -> 0 | ... Z34: =CHOOSE(CF!$G$1,'Capex Allocation'!U32,'Capex Allocation'!U94) -> 0
C35: Pre-operating | K35: =SUM(L35:R35) -> 1 | M35: =CHOOSE(CF!$G$1,'Capex Allocation'!H33,'Capex Allocation'!H95) -> 0.1 | N35: =CHOOSE(CF!$G$1,'Capex Allocation'!I33,'Capex Allocation'!I95) -> 0.25 | O35: =CHOOSE(CF!$G$1,'Capex Allocation'!J33,'Capex Allocation'!J95) -> 0.3 | P35: =CHOOSE(CF!$G$1,'Capex Allocation'!K33,'Capex Allocation'!K95) -> 0.25 | Q35: =CHOOSE(CF!$G$1,'Capex Allocation'!L33,'Capex Allocation'!L95) -> 0.1 | R35: =CHOOSE(CF!$G$1,'Capex Allocation'!M33,'Capex Allocation'!M95) -> 0 | S35: =CHOOSE(CF!$G$1,'Capex Allocation'!N33,'Capex Allocation'!N95) -> 0 | T35: =CHOOSE(CF!$G$1,'Capex Allocation'!O33,'Capex Allocation'!O95) -> 0 | ... Z35: =CHOOSE(CF!$G$1,'Capex Allocation'!U33,'Capex Allocation'!U95) -> 0
C36: Professional fee | K36: =SUM(L36:R36) -> 1 | M36: =CHOOSE(CF!$G$1,'Capex Allocation'!H34,'Capex Allocation'!H96) -> 0.1 | N36: =CHOOSE(CF!$G$1,'Capex Allocation'!I34,'Capex Allocation'!I96) -> 0.25 | O36: =CHOOSE(CF!$G$1,'Capex Allocation'!J34,'Capex Allocation'!J96) -> 0.3 | P36: =CHOOSE(CF!$G$1,'Capex Allocation'!K34,'Capex Allocation'!K96) -> 0.25 | Q36: =CHOOSE(CF!$G$1,'Capex Allocation'!L34,'Capex Allocation'!L96) -> 0.1 | R36: =CHOOSE(CF!$G$1,'Capex Allocation'!M34,'Capex Allocation'!M96) -> 0 | S36: =CHOOSE(CF!$G$1,'Capex Allocation'!N34,'Capex Allocation'!N96) -> 0 | T36: =CHOOSE(CF!$G$1,'Capex Allocation'!O34,'Capex Allocation'!O96) -> 0 | ... Z36: =CHOOSE(CF!$G$1,'Capex Allocation'!U34,'Capex Allocation'!U96) -> 0
C37: Commission | K37: =SUM(L37:R37) -> 1 | M37: =CHOOSE(CF!$G$1,'Capex Allocation'!H35,'Capex Allocation'!H97) -> 0.1 | N37: =CHOOSE(CF!$G$1,'Capex Allocation'!I35,'Capex Allocation'!I97) -> 0.25 | O37: =CHOOSE(CF!$G$1,'Capex Allocation'!J35,'Capex Allocation'!J97) -> 0.3 | P37: =CHOOSE(CF!$G$1,'Capex Allocation'!K35,'Capex Allocation'!K97) -> 0.25 | Q37: =CHOOSE(CF!$G$1,'Capex Allocation'!L35,'Capex Allocation'!L97) -> 0.1 | R37: =CHOOSE(CF!$G$1,'Capex Allocation'!M35,'Capex Allocation'!M97) -> 0 | S37: =CHOOSE(CF!$G$1,'Capex Allocation'!N35,'Capex Allocation'!N97) -> 0 | T37: =CHOOSE(CF!$G$1,'Capex Allocation'!O35,'Capex Allocation'!O97) -> 0 | ... Z37: =CHOOSE(CF!$G$1,'Capex Allocation'!U35,'Capex Allocation'!U97) -> 0
C38: Contingency | K38: =SUM(L38:R38) -> 1 | M38: =CHOOSE(CF!$G$1,'Capex Allocation'!H36,'Capex Allocation'!H98) -> 0.1 | N38: =CHOOSE(CF!$G$1,'Capex Allocation'!I36,'Capex Allocation'!I98) -> 0.25 | O38: =CHOOSE(CF!$G$1,'Capex Allocation'!J36,'Capex Allocation'!J98) -> 0.3 | P38: =CHOOSE(CF!$G$1,'Capex Allocation'!K36,'Capex Allocation'!K98) -> 0.25 | Q38: =CHOOSE(CF!$G$1,'Capex Allocation'!L36,'Capex Allocation'!L98) -> 0.1 | R38: =CHOOSE(CF!$G$1,'Capex Allocation'!M36,'Capex Allocation'!M98) -> 0 | S38: =CHOOSE(CF!$G$1,'Capex Allocation'!N36,'Capex Allocation'!N98) -> 0 | T38: =CHOOSE(CF!$G$1,'Capex Allocation'!O36,'Capex Allocation'!O98) -> 0 | ... Z38: =CHOOSE(CF!$G$1,'Capex Allocation'!U36,'Capex Allocation'!U98) -> 0
C39: Check (=100%)
C41: Hotel 01 - 336 Keys - Allocation %
C42: Land | K42: =SUM(L42:R42) -> 1 | M42: =CHOOSE(CF!$G$1,'Capex Allocation'!H39,'Capex Allocation'!H101) -> 1 | N42: =CHOOSE(CF!$G$1,'Capex Allocation'!I39,'Capex Allocation'!I101) -> 0 | O42: =CHOOSE(CF!$G$1,'Capex Allocation'!J39,'Capex Allocation'!J101) -> 0 | P42: =CHOOSE(CF!$G$1,'Capex Allocation'!K39,'Capex Allocation'!K101) -> 0 | Q42: =CHOOSE(CF!$G$1,'Capex Allocation'!L39,'Capex Allocation'!L101) -> 0 | R42: =CHOOSE(CF!$G$1,'Capex Allocation'!M39,'Capex Allocation'!M101) -> 0 | S42: =CHOOSE(CF!$G$1,'Capex Allocation'!N39,'Capex Allocation'!N101) -> 0 | T42: =CHOOSE(CF!$G$1,'Capex Allocation'!O39,'Capex Allocation'!O101) -> 0 | ... Z42: =CHOOSE(CF!$G$1,'Capex Allocation'!U39,'Capex Allocation'!U101) -> 0
C43: Construction (BUA + Parking) | K43: =SUM(L43:R43) -> 1 | M43: =CHOOSE(CF!$G$1,'Capex Allocation'!H40,'Capex Allocation'!H102) -> 0.1 | N43: =CHOOSE(CF!$G$1,'Capex Allocation'!I40,'Capex Allocation'!I102) -> 0.25 | O43: =CHOOSE(CF!$G$1,'Capex Allocation'!J40,'Capex Allocation'!J102) -> 0.3 | P43: =CHOOSE(CF!$G$1,'Capex Allocation'!K40,'Capex Allocation'!K102) -> 0.25 | Q43: =CHOOSE(CF!$G$1,'Capex Allocation'!L40,'Capex Allocation'!L102) -> 0.1 | R43: =CHOOSE(CF!$G$1,'Capex Allocation'!M40,'Capex Allocation'!M102) -> 0 | S43: =CHOOSE(CF!$G$1,'Capex Allocation'!N40,'Capex Allocation'!N102) -> 0 | T43: =CHOOSE(CF!$G$1,'Capex Allocation'!O40,'Capex Allocation'!O102) -> 0 | ... Z43: =CHOOSE(CF!$G$1,'Capex Allocation'!U40,'Capex Allocation'!U102) -> 0
C44: Infrastructure | K44: =SUM(L44:R44) -> 1 | M44: =CHOOSE(CF!$G$1,'Capex Allocation'!H41,'Capex Allocation'!H103) -> 0.1 | N44: =CHOOSE(CF!$G$1,'Capex Allocation'!I41,'Capex Allocation'!I103) -> 0.25 | O44: =CHOOSE(CF!$G$1,'Capex Allocation'!J41,'Capex Allocation'!J103) -> 0.3 | P44: =CHOOSE(CF!$G$1,'Capex Allocation'!K41,'Capex Allocation'!K103) -> 0.25 | Q44: =CHOOSE(CF!$G$1,'Capex Allocation'!L41,'Capex Allocation'!L103) -> 0.1 | R44: =CHOOSE(CF!$G$1,'Capex Allocation'!M41,'Capex Allocation'!M103) -> 0 | S44: =CHOOSE(CF!$G$1,'Capex Allocation'!N41,'Capex Allocation'!N103) -> 0 | T44: =CHOOSE(CF!$G$1,'Capex Allocation'!O41,'Capex Allocation'!O103) -> 0 | ... Z44: =CHOOSE(CF!$G$1,'Capex Allocation'!U41,'Capex Allocation'!U103) -> 0
C45: Landscaping | K45: =SUM(L45:R45) -> 1 | M45: =CHOOSE(CF!$G$1,'Capex Allocation'!H42,'Capex Allocation'!H104) -> 0.1 | N45: =CHOOSE(CF!$G$1,'Capex Allocation'!I42,'Capex Allocation'!I104) -> 0.25 | O45: =CHOOSE(CF!$G$1,'Capex Allocation'!J42,'Capex Allocation'!J104) -> 0.3 | P45: =CHOOSE(CF!$G$1,'Capex Allocation'!K42,'Capex Allocation'!K104) -> 0.25 | Q45: =CHOOSE(CF!$G$1,'Capex Allocation'!L42,'Capex Allocation'!L104) -> 0.1 | R45: =CHOOSE(CF!$G$1,'Capex Allocation'!M42,'Capex Allocation'!M104) -> 0 | S45: =CHOOSE(CF!$G$1,'Capex Allocation'!N42,'Capex Allocation'!N104) -> 0 | T45: =CHOOSE(CF!$G$1,'Capex Allocation'!O42,'Capex Allocation'!O104) -> 0 | ... Z45: =CHOOSE(CF!$G$1,'Capex Allocation'!U42,'Capex Allocation'!U104) -> 0
...

Sheet Sheet1
F2: Capex | G2: Commission
E3: Old | F3: 3591855 | G3: 286749.54
E4: Revised | F4: 3561464.5 | G4: 256359.08
E5: Diff | F5: =F3-F4 -> 30390.455 | G5: =G3-G4 -> 30390.455

Sheet Capex Allocation
B1: MAAD RESIDENTIAL WITH HOTEL - CAPEX | V1: KPMG | W1: 1
B2: All figures in SAR'000 | V2: Management | W2: 2
B3: Asset cost stack (5 assets, sub-units, land), depreciation schedule and variance vs main MAAD model.
F4: Total | H4: 2026 | I4: 2027 | J4: 2028 | K4: 2029 | L4: 2030 | M4: 2031 | N4: =M4+1 -> 2032 | O4: =N4+1 -> 2033 | P4: =O4+1 -> 2034 | Q4: =P4+1 -> 2035 | R4: =Q4+1 -> 2036 | S4: =R4+1 -> 2037 | T4: =S4+1 -> 2038 | U4: =T4+1 -> 2039
B6: Cash Flow Allocation - KPMG
C8: Branded Apartments T2 & T3 - Allocation %
C9: Land | F9: =SUM(H9:U9) -> 1 | H9: 1 | I9: 0 | J9: 0 | K9: 0 | L9: 0 | M9: 0 | N9: 0 | O9: 0 | P9: 0 | Q9: 0 | R9: 0 | S9: 0 | T9: 0 | U9: 0
C10: Construction (BUA + Parking) | F10: =SUM(H10:U10) -> 1 | H10: 0.3 | I10: 0.3 | J10: 0.3 | K10: 0.1 | L10: 0 | M10: 0 | N10: 0 | O10: 0 | P10: 0 | Q10: 0 | R10: 0 | S10: 0 | T10: 0 | U10: 0
C11: Infrastructure | F11: =SUM(H11:U11) -> 1 | H11: 1 | I11: 0 | J11: 0 | K11: 0 | L11: 0 | M11: 0 | N11: 0 | O11: 0 | P11: 0 | Q11: 0 | R11: 0 | S11: 0 | T11: 0 | U11: 0
C12: Landscaping | F12: =SUM(H12:U12) -> 1 | H12: 0 | I12: 0 | J12: 0 | K12: 1 | L12: 0 | M12: 0 | N12: 0 | O12: 0 | P12: 0 | Q12: 0 | R12: 0 | S12: 0 | T12: 0 | U12: 0
C13: Pre-operating | F13: =SUM(H13:U13) -> 1 | H13: 0.311 | I13: 0.294 | J13: 0.294 | K13: 0.101 | L13: 0 | M13: 0 | N13: 0 | O13: 0 | P13: 0 | Q13: 0 | R13: 0 | S13: 0 | T13: 0 | U13: 0
C14: Professional fee | F14: =SUM(H14:U14) -> 1 | H14: 0.3 | I14: 0.3 | J14: 0.3 | K14: 0.1 | L14: 0 | M14: 0 | N14: 0 | O14: 0 | P14: 0 | Q14: 0 | R14: 0 | S14: 0 | T14: 0 | U14: 0
C15: Commission | F15: =SUM(H15:U15) -> 1 | H15: 0.048 | I15: 0.292 | J15: 0.3 | K15: 0.256 | L15: 0.104 | M15: 0 | N15: 0 | O15: 0 | P15: 0 | Q15: 0 | R15: 0 | S15: 0 | T15: 0 | U15: 0
C16: Contingency | F16: =SUM(H16:U16) -> 1 | H16: 0.3 | I16: 0.3 | J16: 0.3 | K16: 0.1 | L16: 0 | M16: 0 | N16: 0 | O16: 0 | P16: 0 | Q16: 0 | R16: 0 | S16: 0 | T16: 0 | U16: 0
C18: Branded Apartments T4 & T5 - Allocation %
C19: Land | F19: =SUM(H19:U19) -> 1 | H19: 1 | I19: 0 | J19: 0 | K19: 0 | L19: 0 | M19: 0 | N19: 0 | O19: 0 | P19: 0 | Q19: 0 | R19: 0 | S19: 0 | T19: 0 | U19: 0
C20: Construction (BUA + Parking) | F20: =SUM(H20:U20) -> 1 | H20: 0.3 | I20: 0.3 | J20: 0.3 | K20: 0.1 | L20: 0 | M20: 0 | N20: 0 | O20: 0 | P20: 0 | Q20: 0 | R20: 0 | S20: 0 | T20: 0 | U20: 0
C21: Infrastructure | F21: =SUM(H21:U21) -> 1 | H21: 1 | I21: 0 | J21: 0 | K21: 0 | L21: 0 | M21: 0 | N21: 0 | O21: 0 | P21: 0 | Q21: 0 | R21: 0 | S21: 0 | T21: 0 | U21: 0
C22: Landscaping | F22: =SUM(H22:U22) -> 1 | H22: 0 | I22: 0 | J22: 0 | K22: 1 | L22: 0 | M22: 0 | N22: 0 | O22: 0 | P22: 0 | Q22: 0 | R22: 0 | S22: 0 | T22: 0 | U22: 0
C23: Pre-operating | F23: =SUM(H23:U23) -> 1 | H23: 0.312 | I23: 0.293 | J23: 0.293 | K23: 0.102 | L23: 0 | M23: 0 | N23: 0 | O23: 0 | P23: 0 | Q23: 0 | R23: 0 | S23: 0 | T23: 0 | U23: 0
C24: Professional fee | F24: =SUM(H24:U24) -> 1 | H24: 0.3 | I24: 0.3 | J24: 0.3 | K24: 0.1 | L24: 0 | M24: 0 | N24: 0 | O24: 0 | P24: 0 | Q24: 0 | R24: 0 | S24: 0 | T24: 0 | U24: 0
C25: Commission | F25: =SUM(H25:U25) -> 1 | H25: 0 | I25: 0.191 | J25: 0.196 | K25: 0.2 | L25: 0.308 | M25: 0.105 | N25: 0 | O25: 0 | P25: 0 | Q25: 0 | R25: 0 | S25: 0 | T25: 0 | U25: 0
C26: Contingency | F26: =SUM(H26:U26) -> 1 | H26: 0.3 | I26: 0.3 | J26: 0.3 | K26: 0.1 | L26: 0 | M26: 0 | N26: 0 | O26: 0 | P26: 0 | Q26: 0 | R26: 0 | S26: 0 | T26: 0 | U26: 0
C28: Residential Tower 01 - Allocation %
C29: Land | F29: =SUM(H29:U29) -> 1 | H29: 1 | I29: 0 | J29: 0 | K29: 0 | L29: 0 | M29: 0 | N29: 0 | O29: 0 | P29: 0 | Q29: 0 | R29: 0 | S29: 0 | T29: 0 | U29: 0
C30: Construction (BUA + Parking) | F30: =SUM(H30:U30) -> 1 | H30: 0.3 | I30: 0.3 | J30: 0.3 | K30: 0.1 | L30: 0 | M30: 0 | N30: 0 | O30: 0 | P30: 0 | Q30: 0 | R30: 0 | S30: 0 | T30: 0 | U30: 0
C31: Infrastructure | F31: =SUM(H31:U31) -> 1 | H31: 1 | I31: 0 | J31: 0 | K31: 0 | L31: 0 | M31: 0 | N31: 0 | O31: 0 | P31: 0 | Q31: 0 | R31: 0 | S31: 0 | T31: 0 | U31: 0
C32: Landscaping | F32: =SUM(H32:U32) -> 1 | H32: 0 | I32: 0 | J32: 0 | K32: 1 | L32: 0 | M32: 0 | N32: 0 | O32: 0 | P32: 0 | Q32: 0 | R32: 0 | S32: 0 | T32: 0 | U32: 0
C33: Pre-operating | F33: =SUM(H33:U33) -> 1 | H33: 0.312 | I33: 0.293 | J33: 0.293 | K33: 0.102 | L33: 0 | M33: 0 | N33: 0 | O33: 0 | P33: 0 | Q33: 0 | R33: 0 | S33: 0 | T33: 0 | U33: 0
C34: Professional fee | F34: =SUM(H34:U34) -> 1 | H34: 0.3 | I34: 0.3 | J34: 0.3 | K34: 0.1 | L34: 0 | M34: 0 | N34: 0 | O34: 0 | P34: 0 | Q34: 0 | R34: 0 | S34: 0 | T34: 0 | U34: 0
C35: Commission | F35: =SUM(H35:U35) -> 1 | H35: 0.048 | I35: 0.291 | J35: 0.299 | K35: 0.258 | L35: 0.104 | M35: 0 | N35: 0 | O35: 0 | P35: 0 | Q35: 0 | R35: 0 | S35: 0 | T35: 0 | U35: 0
C36: Contingency | F36: =SUM(H36:U36) -> 1 | H36: 0.3 | I36: 0.3 | J36: 0.3 | K36: 0.1 | L36: 0 | M36: 0 | N36: 0 | O36: 0 | P36: 0 | Q36: 0 | R36: 0 | S36: 0 | T36: 0 | U36: 0
C38: Hotel 01 - 336 Keys - Allocation %
C39: Land | F39: =SUM(H39:U39) -> 1 | H39: 1 | I39: 0 | J39: 0 | K39: 0 | L39: 0 | M39: 0 | N39: 0 | O39: 0 | P39: 0 | Q39: 0 | R39: 0 | S39: 0 | T39: 0 | U39: 0
C40: Construction (BUA + Parking) | F40: =SUM(H40:U40) -> 1 | H40: 0.3 | I40: 0.3 | J40: 0.3 | K40: 0.1 | L40: 0 | M40: 0 | N40: 0 | O40: 0 | P40: 0 | Q40: 0 | R40: 0 | S40: 0 | T40: 0 | U40: 0
C41: Infrastructure | F41: =SUM(H41:U41) -> 1 | H41: 1 | I41: 0 | J41: 0 | K41: 0 | L41: 0 | M41: 0 | N41: 0 | O41: 0 | P41: 0 | Q41: 0 | R41: 0 | S41: 0 | T41: 0 | U41: 0
C42: Landscaping | F42: =SUM(H42:U42) -> 1 | H42: 0 | I42: 0 | J42: 0 | K42: 1 | L42: 0 | M42: 0 | N42: 0 | O42: 0 | P42: 0 | Q42: 0 | R42: 0 | S42: 0 | T42: 0 | U42: 0
C43: Pre-operating | F43: =SUM(H43:U43) -> 1 | H43: 0.31 | I43: 0.294 | J43: 0.294 | K43: 0.102 | L43: 0 | M43: 0 | N43: 0 | O43: 0 | P43: 0 | Q43: 0 | R43: 0 | S43: 0 | T43: 0 | U43: 0
C44: Professional fee | F44: =SUM(H44:U44) -> 1 | H44: 0.3 | I44: 0.3 | J44: 0.3 | K44: 0.1 | L44: 0 | M44: 0 | N44: 0 | O44: 0 | P44: 0 | Q44: 0 | R44: 0 | S44: 0 | T44: 0 | U44: 0
C45: Commission | F45: =SUM(H45:U45) -> 1 | H45: 1 | I45: 0 | J45: 0 | K45: 0 | L45: 0 | M45: 0 | N45: 0 | O45: 0 | P45: 0 | Q45: 0 | R45: 0 | S45: 0 | T45: 0 | U45: 0
...

Sheet Debt
B1: MAAD RESIDENTIAL WITH HOTEL - DEBT SCHEDULE
B2: All figures in SAR'000
B3: T1 (SNB Phase 1) + T2 (Phase 2 & 3 capex-driven) debt facilities with interest, fees and capitalised IDC.
C4: DESCRIPTION | D4: Phase | E4: UOM | F4: Total | G4: Unit / Note | H4: 2025 | I4: =H4+1 -> 2026 | J4: =I4+1 -> 2027 | K4: =J4+1 -> 2028 | L4: =K4+1 -> 2029 | M4: =L4+1 -> 2030 | N4: =M4+1 -> 2031 | O4: =N4+1 -> 2032 | P4: =O4+1 -> 2033 | ... V4: =U4+1 -> 2039
B6: ASSUMPTIONS & INPUTS | F6: Value | G6: Unit / Note
C7: Minimum Cash | E7: SAR'000 | F7: 50000
C8: Tranche 1 - SNB Phase 1 (Start-Forward)
C9: Total Land Value | E9: SAR'000 | F9: 2408189
C10: Land Value Phase 2 &3 | E10: SAR'000 | F10: =Capex!$K$210 -> 1350681.9
C11: Land Value Phase 1 | F11: =F9-F10 -> 1057507.1
C12: Pre-Capex Voco | F12: 2624544
C13: Total Pre-Capex Voco | E13: SAR'000 | F13: =SUM(F11:F12) -> 3682051
C14: Pre-Equity Phase 1 | E14: SAR'000 | F14: =F13-F15 -> 1282051
C15: Facility size | E15: SAR'000 | F15: 2400000 | G15: SAR'000 (= 2.4 Bn). Hardcoded drawdown - NOT capex-driven.
C16: Interest rate - operating | E16: % | F16: 0.063 | G16: Per annum
C17: Interest Start | E17: Year | F17: 2026
C18: Tenor | E18: Years | F18: 7 | G18: Years
C19: Drawdown year | E19: Year | F19: 2025 | G19: Year fully drawn (start-forward)
C20: Repayment method | F20: Manual % schedule | G20: From SNB Repayment_V8_NEW (14/04/2026)
C21: Repayment Schedule | E21: % | F21: =SUM(H21:U21) -> 1 | H21: 0 | I21: 0 | J21: 0 | K21: 0.059985706 | L21: 0.066427344 | M21: 0.073810236 | N21: 0.081647406 | O21: 0.47391464 | P21: =1-SUM(H21:O21) -> 0.24421467 | Q21: 0 | R21: 0 | S21: 0 | T21: 0 | U21: 0 | V21: 0
C23: Tranche 2 - Inputs & drivers
C24: Debt Portion | E24: % | F24: 1
C25: Equity Portion | E25: % | F25: =1-F24 -> 0
C26: Interest rate during construction | E26: % | F26: 0.063
C27: Interest rate during operations | E27: % | F27: 0.063
C28: Upfront fee % of facility | E28: % | F28: 0.01
C29: Repayment start year | E29: % | F29: 2028
C30: Repayment Schedule | F30: =SUM(H30:V30) -> 1 | H30: 0 | I30: 0 | J30: 0 | K30: 0.038392147 | L30: 0.054815396 | M30: 0.059982694 | N30: 0.066424008 | O30: 0.07380653 | P30: 0.081643306 | Q30: =1-SUM(H30:P30) -> 0.62493592 | R30: 0 | S30: 0 | T30: 0 | U30: 0 | V30: 0
B32: Funding Phase 1
C34: TRANCHE 1 - SNB Phase 1 Loan
