Workbook

Sheet Architecture
B1: REFM Platform: Architecture Reference
B2: Locked decisions. Every prompt must comply with these. Version 2 (supersedes Modeling_Hub_Prompt.xlsx)
B4: 1. DATA HIERARCHY
B5: Layers | C5: 5 layers: Master Holding → Sub-Project (Fund) → Phase → Asset → Sub-Unit. Single-project users leave Master Holding null. Sub-Project = a fund / zone / standalone project. Phase = sequenced timeline chunk within a Sub-Project. Asset = building or operating entity. Sub-Unit = saleable/operable inventory within an asset.
B6: Master Holding | C6: Optional top-level entity owning master land, takes revenue share % from each Sub-Project, carries master debt for land acquisition. Has its own P&L, cashflow, returns. When present, Sub-Projects contribute equity (cash + land in-kind), pay revenue share, and roll up to Master Holding consolidation.
B7: Sub-Project (Fund) | C7: Independent financing unit. Has its own equity stack (cash + land in-kind), debt, scenarios, returns (FCFE IRR, DDM IRR, MOIC). Can have one or many Phases. Can stand alone (no Master Holding) or be part of a Master Holding.
B8: Phase | C8: Sequenced chunk with own Construction Start / Operations Start / Handover. Multiple Phases can overlap. Each Phase has its own capex curve, can have its own asset list. Phase-level financing is permitted but optional (most cases finance at Sub-Project level).
B9: Asset | C9: Building or operating entity. Has type (locked enum from list of 20, see section 2), category (Sell/Operate/Lease/Hybrid - drives form rendering), one or more Sub-Units. Has own land allocation, capex stack (9 categories), revenue stream(s).
B10: Sub-Unit | C10: Inventory unit. For Sell mode: 1BR/2BR/Studio/Branded Suite/Villa V1/V2 etc. For Operate mode: Twin Key/King Key/Suite. For Lease mode: optional split by floor or zone. Each Sub-Unit has area, count, price/rate, and may have its own pricing escalation.
B11: Securitization | C11: OUT OF SCOPE for v1. Not modeled. Defer to v2.
B13: 1A. AREA PROGRAM (Plot / Zone / Strategy / Sub-Unit physical hierarchy)
B14: Plot | C14: New entity between Phase and Asset. A Plot is a physical land parcel with: name, dimensions (length × width or area), Plot Area sqm, Max FAR, Max GFA (derived = Plot Area × Max FAR), Coverage % (footprint ratio), Footprint sqm (derived = Plot × Coverage), Public Area sqm (Plot − Footprint), Landscape %, Hardscape %, Number of Floors, Number of Podium Floors, Number of Typical Floors. A Phase can have one or many Plots. Each Plot has its own buildable envelope and FAR cap from regulator.
B15: Zone (optional) | C15: Optional sub-division of a Plot. A Plot can have one or many Zones. Each Zone has own dimensions, own Coverage %, own Floor count, own Podium GFA + Typical Floor GFA. Used when a single plot is split into mixed-use clusters (e.g., Project DAS Zone 1A is hotel+office+retail tower, Zone 1B is residences, Zone 2 is low-rise residential, Zone 3 is villas). When a Plot has only one Zone, UI hides the Zone layer.
B16: Strategy allocation per Asset | C16: Each Asset carries Primary Strategy (Develop & Sell / Develop & Lease / Develop & Operate) with Allocation % (default 100%), and optional Secondary Strategy with Allocation % (default 0%). Allocations sum to 100%. Strategy + allocation drive which revenue stream(s) apply at what proportion. Cleaner than current Sell/Operate/Lease/Hybrid enum: Hybrid = any asset with secondary > 0%.
B17: Detailed area cascade per Asset | C17: Asset-level area breakdown (replaces simple GFA → BUA → NSA chain). Per asset: Land Allocation %, Land Area, TBA (Total Built-Up Area), BUA Excluding (MEP & Basement), GFA, GSA / GLA (with GLA/GFA efficiency ratio per sub-unit), MEP Area, Basement Parking allocation, Landscape & Hardscape allocation. Plus building-level: Other Technical Floors, Back of House & Circulation. All driven by per-sub-unit ratios that aggregate up.
B18: Sub-Unit schedule per Asset | C18: Per Asset, schedule of Sub-Units: Studio / 1BR / 2BR / 3BR / Branded Suite / Twin Key / King Key / Villa V1/V2 etc. Each Sub-Unit row: % of Total BUA, BUA sqm, GFA sqm, GSA/GLA sqm, MEP allocation, Basement allocation, Average Unit Size sqm, Number of Units/Keys, Parking Bays per Unit. Auto-aggregates to Asset Total/Average row.
B19: Parking calculation engine | C19: Per residential Sub-Unit: Parking Bays/Unit ratio (typical: Studio 1.0, 1BR 1.0, 2BR 1.6, 3BR 2.0). Per commercial Asset: Parking Bays per 25 sqm of GFA (Hotels typically 1 bay per key or per 35 sqm GFA, Offices 1 bay per 25 sqm GFA, Retail 1 bay per 25 sqm GFA). Then: Surface Parking Area + Vertical Parking Area + Basement Parking Area with Bay Size sqm (typically 25 surface, 40 vertical, 44 basement) + Number of Basement Floors derived = Total Parking Bays / (Basement Floor Area × Basement Efficiency / Bay Size). Drives basement capex significantly.
B20: Podium vs Typical Floor | C20: Critical for tower-on-podium designs. Podium has higher Coverage % (typically 0.65-0.75) and houses retail/hotel/offices/amenities. Typical Floors have lower Coverage % (typically 0.45-0.65) and house residences. Calculated separately: Podium GFA = Footprint × Number of Podium Floors. Typical Floor GFA = Typical Floor Coverage × Plot × Number of Typical Floors. Sum = Total GFA per Plot.
B21: 2. ASSET TYPE CATALOG
B22: Pre-built types (20) | C22: Sell category: Branded Villas, Branded Apartments, High-end Villas, High-end Apartments, Class B Apartments. Operate category: Hotel 4-star, Hotel 5-star, Resort, Serviced Apartments, Senior Living, Student Housing. Lease category: Retail, Office, Industrial, Healthcare, Self-Storage, Data Center. Mixed/Special: Marina, Cinema, Mixed-Use.
B23: Custom types | C23: User can add custom asset types. Required fields: name (string), category (dropdown: Sell / Operate / Lease / Hybrid). Category drives form rendering, Sell shows units × price form, Operate shows occupancy × ADR form, Lease shows area × rate form, Hybrid shows multiple stream forms.
B24: Category enum | C24: Sell, Operate, Lease, Hybrid. Locked. Hybrid asset can have 2+ revenue streams (e.g., serviced apartments selling AND operating same units; mixed-use building leasing podium and operating hotel floors). Each stream is configured separately within the Hybrid asset.
B25: Type → P&L mapping | C25: Sell types use revenue recognition + receivables roll-forward. Operate types use full Uniform System of Accounts P&L (see section 6). Lease types use NOI = Revenue − OpEx. Hybrid types compose multiple.
B27: 3. CURRENCY
B28: Single currency per project | C28: v1 limitation. Set at Sub-Project creation. All values in that currency. Master Holding currency = Sub-Projects currency (must match).
B29: Multi-currency | C29: DEFERRED to v2.
B31: 4. SCENARIO SYSTEM
B32: Three primary scenarios | C32: Base / Management / Upside. Each is a named scenario stored as a delta over Base assumptions for: occupancy curves, ADR growth, sale velocity, down payment %, escalation, payment plan installments, rental growth, vacancy.
B33: Additional scenarios | C33: User can add unlimited additional named scenarios. UI surfaces the 3 primaries by default; user accesses extras via a 'More scenarios' menu.
B34: Active scenario | C34: Toggle in Topbar drives display. All KPIs, charts, exports reflect active scenario.
B35: Sensitivity inputs | C35: Per scenario, user can override: occupancy %, ADR growth %, ADR base, sale velocity (units sold per year curve), down payment %, escalation %, payment plan installments, rental growth %, vacancy %. Other inputs inherit from Base.
B36: Final Dashboard scenario toggle | C36: Module 11 dashboard has live scenario switcher. KPIs, charts, returns refresh on toggle without reload.
B38: 5. FINANCING STRUCTURE
B39: Tranches | C39: Up to 3 financing tranches per Sub-Project, with seniority order (1=most senior). Each tranche has: name, principal amount or % of capex, term, interest rate (fixed only for v1), drawdown schedule (linear / s-curve / custom %), repayment method (fixed / cash sweep / balloon), repayment start period. Standard pattern: Senior + Mezzanine + Equity.
B40: Equity composition | C40: Equity = Cash + Land In-kind. Both contribute to equity stack. Land in-kind value uses Land Value × parcel allocation. Cash equity drawdowns scheduled separately.
B41: Interest | C41: Fixed rate per tranche for v1. Floating (SAIBOR + premium) deferred to v2. Interest During Construction capitalizes per tranche toggle. Half-period interest convention on drawdowns.
B42: Master Fund debt | C42: If Master Holding exists, it can carry its own debt (typically for land acquisition) separate from Sub-Project debt. Master Holding interest expensed against Master Holding revenue share.
B43: DSCR / ICR | C43: Calculated and displayed per period. DSCR < 1.2x flagged amber, < 1.0x flagged red. Used for monitoring, not for sizing in v1.
B44: Securitization | C44: OUT OF SCOPE.
B46: 6. HOSPITALITY P&L (Uniform System of Accounts for the Lodging Industry, USAH)
...

Sheet Tracker
B1: REFM Platform: Build Tracker | K1: Done
B2: Sequenced execution plan. Each phase pauses for verification before next. | K2: Not Started
K3: In Progress
B4: Ph# | C4: Phase | D4: Deliverable | E4: Status | F4: Start Date | G4: Completion Date | H4: Hours | I4: Dependencies
B5: F0 | C5: Folder restructure | D5: src/hubs/, src/core/, src/shared/, ESLint boundaries, path aliases | E5: Done | I5: Pre-existing
B6: F1 | C6: Design tokens system | D6: src/hubs/modeling/design-tokens/, FAST cells, light+dark, Tailwind wiring, README | E6: Done | I6: Pre-existing
B7: F2 | C7: Excel exporter token retrofit | D7: lib/exporters/excel.ts pure builder, FAST cell colors, fixture script | E7: Done | I7: F1
B8: F3 | C8: PDF exporter token retrofit | D8: lib/exporters/pdf.ts pure builder, FAST cell colors, fixture script | E8: Done | I8: F1
B9: F4 | C9: Module 1 snapshot guard | D9: tests/fixtures/module1-reference.json + scripts/module1-snapshot-diff.ts | E9: Done | I9: F1
B10: F5 | C10: REFM component token retrofit | D10: All 15 REFM files. Phase 4.1-4.15. Hex/rgba grep zero across folder. | E10: Done | I10: F1, F4
B11: F6 | C11: Modeling Hub sidebar shell | D11: /modeling/dashboard sidebar layout, CMS logo, dark mode toggle | E11: Done | I11: F1
B12: F7 | C12: REFM Topbar dark mode toggle | D12: Independent localStorage key, scoped to .app-shell | E12: Done | I12: F5
B13: F8 | C13: Module name editing | D13: ProjectModal edit mode wired, pencil button on Overview + Projects | E13: Done | I13: F5
B14: M1.R | C14: Module 1 typed-shape refactor | D14: Lift hardcoded asset enum to AssetClass[]; replace single-phase model with Phase[]; normalize residentialCosts/hospitalityCosts/retailCosts into a single costs[] keyed by assetId. Calculations bit-identical (snapshot diff exit 0). Persistence migrator handles old refm_v2 shape. | E14: Done | F14: 46144 | G14: 46144 | H14: 8 | I14: F4 snapshot
B15: M1.5 | C15: Module 1 hierarchy upgrade | D15: Add Master Holding (optional) → Sub-Project → Phase → Asset → Sub-Unit support to Module 1. UI gains Hierarchy tab (5th tab) for managing layers. Existing Timeline/Area/Costs/Financing tabs remain but operate per-Phase. | E15: Done | F15: 46144 | G15: 46144 | H15: 12 | I15: M1.R
B16: M1.5b | C16: Hierarchy UX polish | D16: First-time empty state with guided CTA. Inline tooltips on each layer (Master Holding, Sub-Project, Phase, Asset, Sub-Unit) explaining what they are and when to use. Optional Quick Setup wizard for single-project / single-phase users (collapses 5 layers into one form). Clearer visual hierarchy (parent-child indentation, expand/collapse, breadcrumb on selection). Empty-state illustrations at each level. Light + dark verified. | E16: Done | F16: 46144 | G16: 46144 | H16: 6 | I16: M1.5
B17: M1.6 | C17: Module 1 Supabase persistence | D17: Migrate from localStorage to Supabase tables refm_projects, refm_project_versions. Per-user RLS. localStorage becomes cache. Migrator uploads existing data on first save. | E17: Done | F17: 46144 | G17: 46144 | H17: 6 | I17: M1.5
B18: M1.7 | C18: Module 1 Area Program | D18: Add Plot and optional Zone entities between Phase and Asset. Add Strategy allocation per Asset (Primary + Secondary with %). Add detailed area cascade per Asset (TBA, BUA Excl, GFA, GSA/GLA, MEP, Basement, Landscape, Hardscape, Other Technical, Back of House). Add Sub-Unit schedule with parking ratios. Add Podium vs Typical Floor split. Add parking calculation engine (surface, vertical, basement). New 'Area Program' tab in Module 1. | E18: Done | F18: 46144 | G18: 46144 | H18: 16 | I18: M1.6
B19: M1.8 | C19: Smart Project Creation Wizard | D19: 3-step wizard at project creation. Asks structure questions (fund/single, phases, plots, project type, assets). Pre-creates hierarchy matching answers. User lands in populated workspace, not empty Hierarchy tab. Progressive disclosure: hidden layers reveal via "+ Add Phase / Plot / Enable Master Holding" buttons. | E19: Done | F19: 46145 | G19: 46145 | H19: 8 | I19: M1.7
B20: M2.1 | C20: Module 2, Revenue: Sell stream | D20: Per-asset Sell mode: Sub-Units × price grid, indexation, pre-sale velocity schedule, down payment %, payment plan installments, cash collection cohort matrix, revenue recognition profile, sales during operation, receivables roll-forward, sales commission. Outputs to Module1Exports interface for downstream modules. | E20: Not started | H20: 14 | I20: M1.7
B21: M2.2 | C21: Module 2, Revenue: Operate stream (USAH) | D21: Per-asset Operate mode: Keys × Days × Occupancy = Occupied, ADR + ADR growth, F&B as % of Rooms or per-occupied, Spa, Other. Departmental Revenue + Departmental Expenses + Departmental Income + Undistributed (A&G/Marketing/POM/Utilities) + GOP + Base Mgmt Fee + Adjusted GOP + Fixed (Insurance/FF&E Reserve/Property Tax/Land Lease) + Incentive Mgmt Fee. EBITDA after FF&E Reserve. PAR + POR KPIs. Multi-scenario occupancy curves. | E21: Not started | H21: 12 | I21: M1.7
B22: M2.3 | C22: Module 2, Revenue: Lease stream | D22: Per-asset Lease mode: Total Lease Area, Loading factor, Vacancy %, Rent/sqm, Rental Growth Rate, OpEx (% of revenue or itemized). NOI = Revenue − OpEx. | E22: Not started | H22: 6 | I22: M1.7
B23: M2.4 | C23: Module 2, Revenue: Hybrid composition | D23: Hybrid asset combines 2+ streams (e.g., serviced apartments Sell + Operate same units). Streams configured separately, roll up to single asset P&L. Common patterns pre-built: Serviced Apartments, Mixed-Use Building (Lease podium + Operate hotel). | E23: Not started | H23: 6 | I23: M2.1, M2.2, M2.3
B24: M2.5 | C24: Module 2 UI tabs | D24: Tabs per Asset: Stream config, Pricing/ADR/Rent, Schedules (velocity/occupancy/vacancy), Outputs (per-period revenue + collections). FAST cells throughout. | E24: Not started | H24: 10 | I24: M2.1-M2.4
B25: M2.6 | C25: Module 2 sample fixture + snapshot guard | D25: Add Module 2 to scripts/snapshot-diff. Cover Sell + Operate + Lease + Hybrid sample assets. Reference numbers verified against MAAD + Hospitality fixture patterns. | E25: Not started | H25: 4 | I25: M2.5
B26: M3 | C26: Module 3, Operating Expenses | D26: Beyond hospitality direct opex (handled in M2.2): corporate overhead (e.g., New Company Costs SAR 2M/year), Zakat/Tax %, Working Capital days. Per-period schedules. Outputs ready for M5 financial statements. | E26: Not started | H26: 8 | I26: M2
B27: M4.1 | C27: Module 4, Project IRR / Equity IRR | D27: Unlevered Project IRR (capex out, NOI/EBITDA in, terminal value in). Levered Equity IRR (after debt service). Per Sub-Project. Per Master Holding (when present). | E27: Not started | H27: 6 | I27: M2, M3
B28: M4.2 | C28: Module 4, FCFE + DDM dual returns | D28: FCFE IRR/MOIC and DDM IRR/MOIC computed in parallel per Sub-Project. Shareholder split when JV (e.g., 65/35) drives per-investor returns. Match Hospitality + Alma model patterns. | E28: Not started | H28: 6 | I28: M4.1
B29: M4.3 | C29: Module 4, NPV, MOIC, Payback, Margins | D29: NPV at user-discount-rate, MOIC = total distributions / total equity, Payback Year (cumulative cash crosses zero), Development Margin = (Revenue − Cost) / Revenue, Profit on Cost = (Revenue − Cost) / Cost, Cash-on-Cash annual. | E29: Not started | H29: 4 | I29: M4.1
B30: M4.4 | C30: Module 4, DSCR, ICR, LTC, LTV per period | D30: Coverage and leverage ratios per period. DSCR < 1.2x amber, < 1.0x red. Display in returns dashboard. | E30: Not started | H30: 4 | I30: M4.1
B31: M4.5 | C31: Module 4, Terminal Value | D31: Terminal Value computed at terminal year per asset: capitalized NOI / cap rate, OR multiple × final-year EBITDA, OR exit price. User picks method per asset. Selling Cost % deducted. | E31: Not started | H31: 4 | I31: M4.1
... B59: L3 | C59: Launch | D59: Public REFM availability for app.financialmodelerpro.com modeling hub. Module 10 (Collaborate) post-launch v1.5. | E59: Not started | H59: 4 | I59: L2
C60: TOTAL | H60: 348

Sheet Prompts
B1: REFM Platform: Paste-Ready Prompts
B2: Each prompt is one execution unit for Claude Code. Read the Architecture sheet first. Comply with all 15 sections. Snapshot diff exit 0 mandatory for any change touching Module 1 calculations.
B4: Ph# | C4: Phase | D4: Prompt | E4: Status | F4: Start Date | G4: Completion Date
B5: M1.R | C5: Module 1 typed-shape refactor | D5: Refactor Module 1 to support multi-asset and multi-phase data shape without changing calculation outputs. Read Architecture sheet sections 1, 2, 8, 14 before starting. Target outcome: 1. Replace the hardcoded `'residential' | 'hospitality' | 'retail'` string union with a typed AssetClass[] array. Each asset has: id, name, type (from 20 pre-built or custom string), category ('Sell' | 'Operate' | 'Lease' | 'Hybrid'), allocationPct (% of project GFA), deductPct, efficiencyPct. 2. Replace the single Construction-Operations timeline with a Phase[] array. Each phase has: id, name, constructionStart, constructionPeriods, operationsStart, operationsPeriods, overlapPeriods. Single-phase users have one phase. Multi-phase users add more. 3. Normalize the parallel `residentialCosts[] / hospitalityCosts[] / retailCosts[]` arrays into a single `costs[]` keyed by `assetId` (and optional `phaseId` for phase-specific costs). 4. Lift state from 30+ useState hooks in RealEstatePlatform.tsx into a Zustand store at `src/hubs/modeling/platforms/refm/lib/state/module1-store.ts`. Store exposes typed selectors and actions. Component reads via selectors. 5. Persistence migrator: on load, detect old refm_v2 shape (3 hardcoded asset arrays) and convert to new shape (1 normalized assets[] + 1 normalized costs[] + 1 phases[] with single phase). Preserve all data. 6. Calculations bit-identical. Snapshot diff `npx tsx scripts/module1-snapshot-diff.ts` must exit 0 against existing baseline. Constraints: - Do not introduce new calculations. Only restructure data and adapt existing calc functions to read from new shape. - buildAssetFinancing, calculateItemTotal, distributeCost, getAreas, allocateToAssets, calcItemTotalV14, getAssetDirectCost all preserve their signatures externally; internally they iterate the new assets[] array. - Same-for-all mode preserved as a UI/state preference, propagating non-land cost lines across all assets in costs[]. - All 4 Module 1 tabs (Timeline / Area / Costs / Financing) continue rendering correctly, in light + dark. - FAST cell convention preserved. Verification: - Snapshot diff exit 0 - Type-check + build pass - Manually: load existing project, verify all numbers identical - Eyeball Module 1 in light + dark One commit. Push to main. | E5: =Tracker!E14 -> Done | F5: =Tracker!F14 -> 46144 | G5: =Tracker!G14 -> 46144
B6: M1.5 | C6: Module 1 hierarchy upgrade | D6: Add the 5-layer hierarchy to Module 1. Read Architecture sheet section 1 before starting. Target outcome: 1. New types: MasterHolding (optional), SubProject, Phase, Asset, SubUnit. SubProject has: id, name, currency, masterHoldingId (nullable), revenueShareToMaster (% if linked to master). 2. New "Hierarchy" tab in Module 1 (5th tab, becomes default landing of Module 1). UI: tree view of MasterHolding (optional) → SubProjects → Phases → Assets → SubUnits with create/edit/reorder controls. 3. Existing tabs (Timeline / Area / Costs / Financing) operate within a selected Phase context. Phase selector at top of these tabs. 4. SubUnit: per-asset inventory with name, count or area, price/rate (auto-driven by asset category Sell/Operate/Lease). 5. Master Holding: optional. When present, has its own land cost, debt, revenue share % from sub-projects, P&L, returns. UI shows separate "Master Holding" entity in Hierarchy tab. 6. Persistence: extend Zustand store and Supabase schema (preview only, actual Supabase migration in M1.6). Migrator handles old single-project shape. Constraints: - Single-project users (no Master Holding, one Sub-Project, one Phase) get a streamlined UX. Master Holding panel hidden until enabled. Multi-phase users see Phase selector. Default new project: 1 Sub-Project + 1 Phase + empty assets array. - Snapshot diff still passes for the single-phase fixture. - FAST cells throughout new Hierarchy tab. Verification: - Snapshot diff exit 0 (single-phase legacy fixture) - New fixture for multi-phase + multi-asset case added to tests/fixtures/ - Type-check + build pass - Eyeball: create a 3-phase project, add assets to each phase, switch phases, verify isolation | E6: =Tracker!E15 -> Done | F6: =Tracker!F15 -> 46144 | G6: =Tracker!G15 -> 46144
B7: M1.5b | C7: Hierarchy UX polish | D7: Polish the Hierarchy tab UX for first-time users. The 5-layer structure is correct but currently feels heavy on first visit. Read Architecture sheet sections 1, 1A before starting. Reference Phase M1.5 Module1Hierarchy.tsx for current implementation. Target outcome: 1. First-time empty state. When project has zero Sub-Projects (brand new project, just created), show a centered card with: - Title: "Set up your project structure" - Two CTA buttons side by side: - "Quick Setup" (primary, navy button) - opens wizard - "Manual Setup" (secondary, outline button) - shows current Hierarchy tree directly - Brief 1-line description under each button explaining when to use which. 2. Quick Setup wizard. Modal-style multi-step form for single-project / single-phase users (90% case): - Step 1: Sub-Project basics (name, currency, location, status) - Step 2: Timeline (construction periods, operations periods, overlap) - Step 3: First Asset (asset type from 20 pre-built dropdown, category auto-derived, allocation %, deduct %, efficiency %) - Step 4: Sub-Units for that asset (skip option for users who want to add later) - Final: "Create" button. Wizard creates Sub-Project + 1 Phase + 1 Asset + Sub-Units (if any) in one transaction. - User can skip wizard at any step and switch to Manual mode (preserves what's been entered). - Available again later via "Add Sub-Project" button if user wants to add another sub-project via wizard. 3. Inline tooltips on each layer label. Hover the layer label or click an info icon to see: - Master Holding: "Optional. Use when you have multiple Sub-Projects under one parent entity (e.g., a real estate fund holding 7 funds, each with own land + debt + returns). Most projects skip this." - Sub-Project: "An independent financing unit. One Sub-Project = one fund / project / standalone development. Has its own equity, debt, returns. Most users have just 1 Sub-Project." - Phase: "A sequenced timeline chunk within a Sub-Project. Most projects have 1 Phase. Add more Phases for staged developments where Phase 2 starts construction years after Phase 1." - Asset: "A building or operating entity. One asset = one building or one operating unit type (e.g., 5-Star Hotel, Branded Apartments Tower 1, Retail Podium)." - Sub-Unit: "Inventory inside an Asset. For Sell: 1BR / 2BR / Branded Suite. For Operate: Twin Key / King Key. For Lease: optional split by floor or zone." 4. Visual hierarchy clarity: - Increase indentation per level (currently subtle, needs to be more obvious) - Add expand/collapse chevrons on each level (Sub-Project / Phase / Asset). Default expanded. - Sticky breadcrumb at top when scrolling deep ("FMP Mixed-Used > Phase 1 > Residential") - Subtle background tint per level to reinforce hierarchy (Sub-Project bg navy-pale, Phase bg lighter, Asset bg lightest) 5. Empty-state cards at each level when sub-items missing: - Sub-Project with no Phases: "+ Add first Phase" centered card with brief explainer - Phase with no Assets: "+ Add first Asset" centered card with type picker preview - Asset with no Sub-Units: existing "+ Add Sub-Unit" stays but adds 1-line hint above it 6. Page header context. Top of Hierarchy tab adds: - Quick stats line: "1 Sub-Project, 1 Phase, 3 Assets, 0 Sub-Units" - "Switch to Quick Setup" link (always available, not just empty state) Constraints: - Snapshot diff exit 0 (no calc changes, only UI) - Type-check + build pass - FAST cells throughout (no hardcoded colors) - Light + dark mode both work - Keyboard navigable (tab through wizard steps, Esc to close) - Accessible: tooltips have aria-label, wizard is screen-reader friendly Verification: - Snapshot diff exit 0 - Eyeball: create new project, walk through Quick Setup wizard end-to-end. Then create another project, use Manual Setup. Then open existing migrated project, verify breadcrumb + indentation + tooltips read correctly. Split into 4-6 commits, same per-commit verify+push cadence. | E7: =Tracker!E16 -> Done | F7: =Tracker!F16 -> 46144 | G7: =Tracker!G16 -> 46144
B8: M1.6 | C8: Module 1 Supabase persistence | E8: =Tracker!E17 -> Done | F8: =Tracker!F17 -> 46144 | G8: =Tracker!G17 -> 46144
B9: M1.7 | C9: Module 1 Area Program | D9: Read Architecture sheet sections 1, 1A before starting. Reference Phase M1.5 Module1Hierarchy.tsx for current implementation. | E9: =Tracker!E18 -> Done | F9: =Tracker!F18 -> 46144 | G9: =Tracker!G18 -> 46144
B10: M1.8 | C10: Smart Project Creation Wizard | D10: # Phase M1.8: Smart Project Creation Wizard ## Purpose Replace the current "blank Hierarchy tab" first experience with a guided wizard that asks 3-5 simple questions and pre-creates the project structure. User lands in a populated workspace, not an empty 5-layer tree. ## Problem We Are Solving Current flow: user creates project, lands on Hierarchy tab, sees 5 empty layers (Master Holding, Sub-Project, Phase, Plot, Asset, Sub-Unit), feels overwhelmed. New flow: user answers 3 questions during creation, lands in pre-populated workspace with structure already matching their needs. 90% of users (single project, single phase, single plot, 2-3 assets) never see Master Holding or multi-plot complexity unless they explicitly opt in later. ## Reference Read REFM_Build_Prompts_v2.1.xlsx Architecture sheet sections 1, 1A, 2 before starting. ## Target Outcome ### 1. Replace current "+ New Project" button behavior Currently the New Project button in Projects screen creates an empty project and routes to Hierarchy tab. Change it to open a 3-step wizard modal. ### 2. Wizard Step 1: Project Basics Inputs: - Project Name (required) - Location (required, e.g., "Riyadh, Saudi Arabia") - Currency (default SAR, dropdown from common currencies) - Model Type (radio: Annual / Monthly, default Annual) - Project Start Date (default today + 6 months) - Status (radio: Draft / Active, default Draft) Validation: Name and location required. Show "Continue" disabled until both filled. ### 3. Wizard Step 2: Project Structure Three questions with smart defaults: **Question 1: Is this part of a fund or portfolio?** - Toggle (default OFF) - If ON: enables Master Holding layer in Hierarchy tab. If OFF: Master Holding hidden by default (user can enable later from Hierarchy tab). **Question 2: How many phases?** - Radio: "Single Phase (most projects)" / "Multiple Phases (staged development)" - Default: Single Phase - If Multiple: ask "How many?" with number input (2-10). **Question 3: How many plots?** - Radio: "Single Plot" / "Multiple Plots (large land bank)" - Default: Single Plot - If Multiple: ask "How many?" with number input (2-20). ### 4. Wizard Step 3: Assets Based on user's project type selection, pre-fill suggested assets. **First, ask Project Type:** - Radio: Residential / Hospitality / Retail / Mixed-Use / Office / Custom - Default: Mixed-Use **Then suggest assets based on type:** | Project Type | Default Assets | |--------------|----------------| | Residential | 1 asset: "Residential Tower" (High-end Apartments, Sell, 100%) | | Hospitality | 1 asset: "Hotel" (Hotel 5-star, Operate, 100%) | | Retail | 1 asset: "Retail Center" (Retail, Lease, 100%) | | Office | 1 asset: "Office Tower" (Office, Lease, 100%) | | Mixed-Use | 3 assets: Residential Tower (Sell, 50%), Hotel (Operate, 30%), Retail Podium (Lease, 20%) | | Custom | Empty list, user adds manually | User can edit/add/remove assets in this step. For each asset row: - Name (editable) - Type dropdown (20 pre-built + Custom option) - Category (auto-derived from type, or user-set if Custom) - Allocation % (auto-balances to 100 across all assets) - Remove button (if more than 1 asset) - "+ Add Asset" button below Validation: Total allocation must = 100%. Show "Create Project" disabled until valid. ### 5. On "Create Project" Create the project with: - Sub-Project: "Main" (or user-named in Step 1) - Phase 1 (and Phase 2, Phase 3 if user picked Multiple Phases) - Plot 1 (and Plot 2... if user picked Multiple Plots) - Assets pre-created per Step 3 list, all bound to Phase 1 + Plot 1 by default - Single sub-unit per asset auto-created with placeholder values: - Sell: 1 unit, Unit Size = 100 sqm, Price = 0 (user fills later) - Operate: 1 key/unit, quantity = 1 (user fills later) - Lease: 1 area unit, area = 0 (user fills later) - Master Holding: NOT created unless Step 2 Question 1 was ON - Routes to Area Program tab (not Hierarchy tab) since structure is already set up ### 6. Hierarchy Tab Polish When Hierarchy tab is opened on a wizard-created project: - Hide layers user said they don't need (Master Holding, multi-phase complexity, multi-plot complexity) - Show only their actual structure - Top of Hierarchy tab: 3 action buttons always visible - "+ Add Phase" (creates Phase 2, etc.) - "+ Add Plot" (creates Plot 2, etc.) - "Enable Master Holding" toggle (turns on the Master Holding layer if user wants to convert to fund structure later) ### 7. Edit Project Structure Later When user clicks "Enable Master Holding" or "+ Add Phase" or "+ Add Plot" later, the new layer appears in Hierarchy tab with empty state guiding them through setup. No re-wizard. ## Constraints - Snapshot diffs (legacy + multiphase + areaprogram) must all stay exit 0. No calc changes. - Migrator handles old projects: existing projects without wizard preference flags get default "show all layers" behavior (current behavior preserved). - FAST cells throughout wizard. - Light + dark mode both work. - Keyboard navigable (Tab through fields, Enter advances steps). - Esc closes wizard with confirmation if any data entered. - Wizard state preserved if user goes Back to previous step. ## Verification 1. Snapshot diffs exit 0 (all 3 tracks) 2. Type-check + build pass per commit 3. Playwright headless test in `tests/e2e/m18-wizard.spec.ts`: - Create project via wizard with default mixed-use selections - Verify project landed on Area Program tab - Verify Hierarchy tab shows 3 assets - Verify Master Holding layer hidden - Test "Enable Master Holding" reveals layer - Test "+ Add Phase" creates Phase 2 - Screenshots saved to `tests/screenshots/M1.8/` for light + dark 4. `scripts/verify-m18.ts`: - Wizard completion creates expected DB rows - Default asset configs match project type matrix above - Existing projects load unchanged ## Commit Plan Split into 6-8 commits: 1. Wizard component scaffold + 3-step state machine 2. Step 1: Project Basics form 3. Step 2: Structure questions with conditional fields 4. Step 3: Asset list with project-type defaults 5. Create-project transactional handler (creates SP + Phase + Plot + Assets + Sub-Units atomically) 6. Hierarchy tab progressive disclosure (hide unused layers) 7. Hierarchy tab "+ Add Phase / Plot / Enable Master Holding" actions 8. Verification scripts + Playwright + screenshots Per-commit cadence: snapshot diff exit 0, type-check + build pass, push to main. When done, report: commit hashes, files touched per commit, verify-m18.ts output, Playwright screenshots path, pattern decisions, deviations. Begin Phase M1.8. | E10: =Tracker!E19 -> Done | F10: =Tracker!F19 -> 46145 | G10: =Tracker!G19 -> 46145
B11: M2.1 | C11: Module 2 Revenue, Sell stream | E11: =Tracker!E20 -> Not started | F11: =Tracker!F20 -> 0 | G11: =Tracker!G20 -> 0
B12: M2.2 | C12: Module 2 Revenue, Operate stream (USAH) | D12: ## Purpose | E12: =Tracker!E21 -> Not started | F12: =Tracker!F21 -> 0 | G12: =Tracker!G21 -> 0
B13: M2.3 | C13: Module 2 Revenue, Lease stream | E13: =Tracker!E22 -> Not started | F13: =Tracker!F22 -> 0 | G13: =Tracker!G22 -> 0
B14: M2.4 | C14: Module 2 Revenue, Hybrid composition | D14: Replace the current "blank Hierarchy tab" first experience with a guided wizard that asks 3-5 simple questions and pre-creates the project structure. User lands in a populated workspace, not an empty 5-layer tree. | E14: =Tracker!E23 -> Not started | F14: =Tracker!F23 -> 0 | G14: =Tracker!G23 -> 0
B15: M2.5 | C15: Module 2 UI tabs | E15: =Tracker!E24 -> Not started | F15: =Tracker!F24 -> 0 | G15: =Tracker!G24 -> 0
B16: M2.6 | C16: Module 2 snapshot guard | D16: ## Problem We Are Solving | E16: =Tracker!E25 -> Not started | F16: =Tracker!F25 -> 0 | G16: =Tracker!G25 -> 0
B17: M3 | C17: Module 3, Operating Expenses | E17: =Tracker!E26 -> Not started | F17: =Tracker!F26 -> 0 | G17: =Tracker!G26 -> 0
B18: M4.1 | C18: Module 4, Project IRR / Equity IRR | D18: Current flow: user creates project, lands on Hierarchy tab, sees 5 empty layers (Master Holding, Sub-Project, Phase, Plot, Asset, Sub-Unit), feels overwhelmed. | E18: =Tracker!E27 -> Not started | F18: =Tracker!F27 -> 0 | G18: =Tracker!G27 -> 0
B19: M4.2 | C19: Module 4, FCFE + DDM dual returns | E19: =Tracker!E28 -> Not started | F19: =Tracker!F28 -> 0 | G19: =Tracker!G28 -> 0
B20: M4.3 | C20: Module 4, NPV, MOIC, Payback, Margins | D20: New flow: user answers 3 questions during creation, lands in pre-populated workspace with structure already matching their needs. 90% of users (single project, single phase, single plot, 2-3 assets) never see Master Holding or multi-plot complexity unless they explicitly opt in later. | E20: =Tracker!E29 -> Not started | F20: =Tracker!F29 -> 0 | G20: =Tracker!G29 -> 0
B21: M4.4 | C21: Module 4, DSCR, ICR, LTC, LTV | E21: =Tracker!E30 -> Not started | F21: =Tracker!F30 -> 0 | G21: =Tracker!G30 -> 0
B22: M4.5 | C22: Module 4, Terminal Value | D22: ## Reference | E22: =Tracker!E31 -> Not started | F22: =Tracker!F31 -> 0 | G22: =Tracker!G31 -> 0
B23: M5.1 | C23: Module 5, P&L Statement | E23: =Tracker!E32 -> Not started | F23: =Tracker!F32 -> 0 | G23: =Tracker!G32 -> 0
B24: M5.2 | C24: Module 5, Cash Flow Statement | D24: Read REFM_Build_Prompts_v2.1.xlsx Architecture sheet sections 1, 1A, 2 before starting. | E24: =Tracker!E33 -> Not started | F24: =Tracker!F33 -> 0 | G24: =Tracker!G33 -> 0
B25: M5.3 | C25: Module 5, Balance Sheet | E25: =Tracker!E34 -> Not started | F25: =Tracker!F34 -> 0 | G25: =Tracker!G34 -> 0
B26: M5.4 | C26: Module 5, Cash Sweep Waterfall | D26: ## Target Outcome | E26: =Tracker!E35 -> Not started | F26: =Tracker!F35 -> 0 | G26: =Tracker!G35 -> 0
B27: M6 | C27: Module 6, Reports & Visualizations | E27: =Tracker!E36 -> Not started | F27: =Tracker!F36 -> 0 | G27: =Tracker!G36 -> 0
B28: M7.1 | C28: Module 7, Scenario engine | D28: ### 1. Replace current "+ New Project" button behavior | E28: =Tracker!E37 -> Not started | F28: =Tracker!F37 -> 0 | G28: =Tracker!G37 -> 0
B29: M7.2 | C29: Module 7, Sensitivity tables | E29: =Tracker!E38 -> Not started | F29: =Tracker!F38 -> 0 | G29: =Tracker!G38 -> 0
B30: M7.3 | C30: Module 7, Breakeven analysis | D30: Currently the New Project button in Projects screen creates an empty project and routes to Hierarchy tab. Change it to open a 3-step wizard modal. | E30: =Tracker!E39 -> Not started | F30: =Tracker!F39 -> 0 | G30: =Tracker!G39 -> 0
B31: M8.1 | C31: Module 8, Portfolio rollup | E31: =Tracker!E40 -> Not started | F31: =Tracker!F40 -> 0 | G31: =Tracker!G40 -> 0
B32: M8.2 | C32: Module 8, Cross-project allocation | D32: ### 2. Wizard Step 1: Project Basics | E32: =Tracker!E41 -> Not started | F32: =Tracker!F41 -> 0 | G32: =Tracker!G41 -> 0
B33: M9.1 | C33: Module 9, Research agent | E33: =Tracker!E42 -> Not started | F33: =Tracker!F42 -> 0 | G33: =Tracker!G42 -> 0
B34: M9.2 | C34: Module 9, Market Rates agent | D34: Inputs: | E34: =Tracker!E43 -> Not started | F34: =Tracker!F43 -> 0 | G34: =Tracker!G43 -> 0
B35: M9.3 | C35: Module 9, Agent UI integration | D35: {=- project Name (required)} -> #NAME? | E35: =Tracker!E44 -> Not started | F35: =Tracker!F44 -> 0 | G35: =Tracker!G44 -> 0
B36: M11.1 | C36: Module 11, Final Dashboard layout | D36: - Location (required, e.g., "Riyadh, Saudi Arabia") | E36: =Tracker!E45 -> Optional v1.5 | F36: =Tracker!F45 -> 0 | G36: =Tracker!G45 -> 0
B37: M11.2 | C37: Module 11, Charts package | D37: {=- Currency (default SAR, dropdown from common currencies)} -> #NAME? | E37: =Tracker!E46 -> Not started | F37: =Tracker!F46 -> 0 | G37: =Tracker!G46 -> 0
B38: M11.3 | C38: Module 11, Live scenario switcher | D38: - Model Type (radio: Annual / Monthly, default Annual) | E38: =Tracker!E47 -> Not started | F38: =Tracker!F47 -> 0 | G38: =Tracker!G47 -> 0
B39: M12.1 | C39: Module 12, IM PDF builder | D39: - Project Start Date (default today + 6 months) | E39: =Tracker!E48 -> Not started | F39: =Tracker!F48 -> 0 | G39: =Tracker!G48 -> 0
B40: M12.2 | C40: Module 12, IM PPT builder | D40: - Status (radio: Draft / Active, default Draft) | E40: =Tracker!E49 -> Not started | F40: =Tracker!F49 -> 0 | G40: =Tracker!G49 -> 0
B41: M13.1 | C41: Module 13, Excel formula export (Enterprise) | E41: =Tracker!E50 -> Not started | F41: =Tracker!F50 -> 0 | G41: =Tracker!G50 -> 0
...

Sheet Backlog
B1: REFM Platform: Backlog
B2: Polish, UX, and post-MVP items. Picked up after required modules ship.
B4: # | C4: ID | D4: Item | E4: Description | F4: Priority | G4: Hours | H4: When
B5: 1 | C5: B1 | D5: Sample Project template | E5: Pre-built MAAD-like and Project West-like demo projects. New user clicks 'Try Sample' instead of 'New Project', lands in fully-populated dashboard with all numbers, charts, scenarios visible immediately. Drops 'wow' factor for first-time users. | F5: High | G5: 6 | H5: After Module 11
B6: 2 | C6: B2 | D6: Module unlock progressive reveal | E6: As each Module ships through M2 to M11, remove SOON badge from sidebar. By launch, no SOON-locked modules visible. Avoids first impression of 'platform full of locks'. | F6: Medium | H6: Ongoing during build
B7: 3 | C7: B3 | D7: First-time empty state push verification | E7: Re-eyeball Hierarchy tab Quick Setup vs Manual Setup balance after Modules 2 to 11 ship. If users bounce on empty Hierarchy tree, polish the empty state to push Quick Setup harder. | F7: Medium | G7: 4 | H7: After Module 11
B8: 4 | C8: B4 | D8: Module 11 Final Dashboard polish budget | E8: Reserve extra polish time on M11.1 to M11.3. Final Dashboard is the wow moment of the platform: live KPIs, scenario toggle, charts. Invest more here than other modules. Add micro-interactions, transitions, color-graded conditional formatting. | F8: High | G8: 8 | H8: M11.1 to M11.3 phase
B9: 5 | C9: B5 | D9: Project name editing UI nicety | E9: From Phase 4.3 backlog. Currently project name set at creation, edit pencil added in M1.5. Verify edit affordance is discoverable and not buried. | F9: Low | G9: 2 | H9: Pre-launch L1
B10: 6 | C10: B6 | D10: User guide and documentation | E10: Was L1.1. Static /docs/refm-getting-started page covering 5-layer hierarchy with diagram, Quick Setup walkthrough, FAST cell convention legend, scenario system intro, exporting models. Linked from Hierarchy tab and sidebar. | F10: Medium | G10: 8 | H10: Pre-launch L1
B11: 7 | C11: B7 | D11: Cookie scope cross-subdomain fix | E11: From Phase 4 known issue. NextAuth cookies.sessionToken.options.domain set to .financialmodelerpro.com so portal and modeling hub share session across subdomains. Required if user data ever needs to flow between hubs. | F11: Low | G11: 2 | H11: If cross-subdomain feature needed
B12: 8 | C12: B8 | D12: REFM workspace tooltip layer | E12: Tooltips on key terms across all modules: FAR, BUA, GFA, DSCR, IRR, MOIC, NPV, USAH, FCFE, DDM, etc. Hover any acronym to see plain-English explanation. Reduces friction for non-finance users. | F12: Medium | G12: 6 | H12: Pre-launch L1
B13: 9 | C13: B9 | D13: Stale floating rate reminder | E13: From MAAD model review. SAIBOR + premium model is static input. Floating rate sensitivity not modeled. Add as v2 feature when needed by users with floating-rate construction loans. | F13: Low | G13: 8 | H13: v2 post-launch
B14: 10 | C14: B10 | D14: Multi-currency support | E14: From Architecture decision section 3. Single currency per project for v1. Multi-currency (e.g., USD loan inside SAR project) deferred to v2 if institutional users request it. | F14: Low | G14: 12 | H14: v2 post-launch
B15: 11 | C15: B11 | D15: Securitization mode | E15: From Architecture decision section 1. Out of scope for v1 per Ahmad. Add later if user base requests. | F15: Low | G15: 16 | H15: v2 post-launch
B16: 12 | C16: B12 | D16: Floating interest rate engine | E16: From Architecture decision section 5. Fixed rate per tranche for v1. SAIBOR + premium floating rate option deferred to v2. | F16: Low | G16: 8 | H16: v2 post-launch
B17: 13 | C17: B13 | D17: In-app interactive Investment Memorandum | E17: From Architecture decision section 10. v1 ships PDF + PPT export of IM. Interactive in-app IM view (live tables, drill-downs) deferred to v2. | F17: Low | G17: 16 | H17: v2 post-launch
B18: 14 | C18: B14 | D18: Authenticated API path Playwright tests | E18: From M1.6 verification gap. Current verify-m16.ts tests 401 gates but not authed happy path because NextAuth session cookie minting is browser-only. Add full E2E with Playwright session injection. | F18: Medium | G18: 4 | H18: Pre-launch L1
B19: 15 | C19: B15 | D19: Module 1 hierarchy onboarding video | E19: 30 to 60 second video walkthrough of 5-layer hierarchy. Embedded in Hierarchy tab empty state. Optional viewing. | F19: Low | G19: 4 | H19: Pre-launch L1
